<?xml version="1.0" ?>
<robot name="hdr35_20_with_gripper_fixed">
  <!--
===================================================================================
HDR35_20 + RH56F1_R (Gripper as Fixed End Effector)
For cuRobo: Only arm joints (6-DOF), gripper is fixed
Structure: HDR35_20 arm (6-DOF) + RH56F1_R as single fixed link
===================================================================================
-->
  <material name="ivory">
    <color rgba="1.0 0.945 0.773 1.0" />
  </material>
  <material name="black">
    <color rgba="0.2 0.2 0.2 1.0" />
  </material>
  <material name="gray">
    <color rgba="0.3 0.3 0.3 1.0" />
  </material>
  <link name="base_link" />
  <link name="base_body_link">
    <visual>
      <geometry>
        <mesh filename="meshes/hdr35_20/visual/base_body.stl" scale="0.001 0.001 0.001" />
      </geometry>
      <material name="ivory" />
    </visual>
    <collision>
      <geometry>
        <mesh filename="meshes/hdr35_20/collision/base_body.stl" scale="0.001 0.001 0.001" />
      </geometry>
    </collision>
    <inertial>
      <mass value="118.90" />
      <origin rpy="0 0 0" xyz="0.0 0 0.1" />
      <inertia ixx="2.7198" ixy="0.0" ixz="0.0" iyy="4.4954" iyz="0.0" izz="6.3413" />
    </inertial>
  </link>
  <link name="lower_frame_link">
    <visual>
      <geometry>
        <mesh filename="meshes/hdr35_20/visual/lower_frame.stl" scale="0.001 0.001 0.001" />
      </geometry>
      <material name="ivory" />
    </visual>
    <collision>
      <geometry>
        <mesh filename="meshes/hdr35_20/collision/lower_frame.stl" scale="0.001 0.001 0.001" />
      </geometry>
    </collision>
    <inertial>
      <mass value="147.17" />
      <origin rpy="0 0 0" xyz="0.0 0 0.2" />
      <inertia ixx="7.5400" ixy="0.0" ixz="0.0" iyy="8.1593" iyz="0.0" izz="6.2706" />
    </inertial>
  </link>
  <link name="upper_frame_link">
    <visual>
      <geometry>
        <mesh filename="meshes/hdr35_20/visual/upper_frame.stl" scale="0.001 0.001 0.001" />
      </geometry>
      <material name="ivory" />
    </visual>
    <collision>
      <geometry>
        <mesh filename="meshes/hdr35_20/collision/upper_frame.stl" scale="0.001 0.001 0.001" />
      </geometry>
    </collision>
    <inertial>
      <mass value="68.63" />
      <origin rpy="0 0 0" xyz="0.0 0.0 -0.04" />
      <inertia ixx="7.9244" ixy="0.0" ixz="0.0" iyy="0.7434" iyz="0.0" izz="8.2104" />
    </inertial>
  </link>
  <link name="arm_link">
    <visual>
      <geometry>
        <mesh filename="meshes/hdr35_20/visual/arm.stl" scale="0.001 0.001 0.001" />
      </geometry>
      <material name="ivory" />
    </visual>
    <collision>
      <geometry>
        <mesh filename="meshes/hdr35_20/collision/arm.stl" scale="0.001 0.001 0.001" />
      </geometry>
    </collision>
    <inertial>
      <mass value="73.93" />
      <origin rpy="0 0 0" xyz="0 0 0" />
      <inertia ixx="1.7700" ixy="0.0" ixz="0.0" iyy="6.6691" iyz="0.0" izz="7.1773" />
    </inertial>
  </link>
  <link name="wrist_body_link">
    <visual>
      <geometry>
        <mesh filename="meshes/hdr35_20/visual/wrist_body.stl" scale="0.001 0.001 0.001" />
      </geometry>
      <material name="ivory" />
    </visual>
    <collision>
      <geometry>
        <mesh filename="meshes/hdr35_20/collision/wrist_body.stl" scale="0.001 0.001 0.001" />
      </geometry>
    </collision>
    <inertial>
      <mass value="20.15" />
      <origin rpy="0 0 0" xyz="0 0 0" />
      <inertia ixx="0.0706" ixy="0.0" ixz="0.0" iyy="0.1553" iyz="0.0" izz="0.1601" />
    </inertial>
  </link>
  <link name="wrist_holder_link">
    <visual>
      <geometry>
        <mesh filename="meshes/hdr35_20/visual/wrist_holder.stl" scale="0.001 0.001 0.001" />
      </geometry>
      <material name="ivory" />
    </visual>
    <collision>
      <geometry>
        <mesh filename="meshes/hdr35_20/collision/wrist_holder.stl" scale="0.001 0.001 0.001" />
      </geometry>
    </collision>
    <inertial>
      <mass value="11.26" />
      <origin rpy="0 0 0" xyz="0 0 0" />
      <inertia ixx="0.0800" ixy="0.0" ixz="0.0" iyy="0.1130" iyz="0.0" izz="0.0938" />
    </inertial>
  </link>
  <link name="flange_link">
    <visual>
      <origin rpy="0 0 0" xyz="0 0 0" />
      <geometry>
        <mesh filename="meshes/hdr35_20/visual/flange.stl" scale="0.001 0.001 0.001" />
      </geometry>
      <material name="gray" />
    </visual>
    <collision>
      <origin rpy="0 0 0" xyz="0 0 0" />
      <geometry>
        <mesh filename="meshes/hdr35_20/collision/flange.stl" scale="0.001 0.001 0.001" />
      </geometry>
    </collision>
    <inertial>
      <mass value="0.79" />
      <origin rpy="0 0 0" xyz="0.005 0 0" />
      <inertia ixx="0.0022" ixy="0.0" ixz="0.0" iyy="0.0011" iyz="0.0" izz="0.0011" />
    </inertial>
  </link>
  <joint name="base_link-base_body_link" type="fixed">
    <origin rpy="0 0 0" xyz="0 0 0" />
    <parent link="base_link" />
    <child link="base_body_link" />
  </joint>
  <joint name="j1" type="revolute">
    <parent link="base_body_link" />
    <child link="lower_frame_link" />
    <origin rpy="0 0 0" xyz="0 0 0" />
    <axis xyz="0 0 1" />
    <limit effort="3078.7" lower="-3.141" upper="3.141" velocity="3.141" />
  </joint>
  <joint name="j2" type="revolute">
    <parent link="lower_frame_link" />
    <child link="upper_frame_link" />
    <origin rpy="1.5708 0 0" xyz="0.15 0.08 0.56" />
    <axis xyz="0 0 1" />
    <limit effort="3169.7" lower="-2.3558" upper="1.5702" velocity="3.141" />
  </joint>
  <joint name="j3" type="revolute">
    <parent link="upper_frame_link" />
    <child link="arm_link" />
    <origin rpy="0 0 0" xyz="0 0.87 -0.04" />
    <axis xyz="0 0 1" />
    <limit effort="1507.0" lower="-1.396" upper="3.141" velocity="3.316" />
  </joint>
  <joint name="j4" type="revolute">
    <parent link="arm_link" />
    <child link="wrist_body_link" />
    <origin rpy="0 0 0" xyz="0.828 0.175 0.1415" />
    <axis xyz="1 0 0" />
    <limit effort="259.0" lower="-6.283" upper="6.283" velocity="5.410" />
  </joint>
  <joint name="j5" type="revolute">
    <parent link="wrist_body_link" />
    <child link="wrist_holder_link" />
    <origin rpy="0 0 0" xyz="0.195 0.0 0.04" />
    <axis xyz="0 0 1" />
    <limit effort="240.4" lower="-2.181" upper="2.181" velocity="5.410" />
  </joint>
  <joint name="j6" type="revolute">
    <parent link="wrist_holder_link" />
    <child link="flange_link" />
    <origin rpy="-1.5708 0 0" xyz="0.175 0 -0.0375" />
    <axis xyz="1 0 0" />
    <limit effort="215.6" lower="-6.283" upper="6.283" velocity="7.330" />
  </joint>
  <link name="gripper_fixed">
    <inertial>
      <origin xyz="0 0 0.05" rpy="0 0 0" />
      <mass value="0.5" />
      <inertia ixx="0.001" ixy="0" ixz="0" iyy="0.001" iyz="0" izz="0.001" />
    </inertial>
    <visual>
      <origin xyz="0 0 0" rpy="0 0 0" />
      <geometry>
        <mesh filename="meshes/RH56F1_R/base_link.STL" />
      </geometry>
    </visual>
    <collision>
      <origin xyz="0 0 0.05" rpy="0 0 0" />
      <geometry>
        <box size="0.1 0.1 0.1" />
      </geometry>
    </collision>
  </link>
  <joint name="flange_to_gripper" type="fixed">
    <origin rpy="0 0 0" xyz="0 0 0" />
    <parent link="flange_link" />
    <child link="gripper_fixed" />
  </joint>
</robot>