<?xml version="1.0" ?>
<!-- =================================================================================== -->
<!-- |    This document was autogenerated by xacro from install/hdr_description/share/hdr_description/urdf/hydex.urdf.xacro | -->
<!-- |    EDITING THIS FILE BY HAND IS NOT RECOMMENDED                                 | -->
<!-- =================================================================================== -->
<robot name="hydex">
  <link name="world"/>
  <!-- =================================================================================== -->
  <!-- Modified for cuRobo usage -->
  <!-- - Changed world link to base_link (root link) -->
  <!-- - Removed base link (renamed to base_body_link) -->
  <!-- - Removed motor links (motor_s, motor_h, motor_v) -->
  <!-- - Changed mesh paths to relative paths -->
  <!-- =================================================================================== -->
  <material name="rh56_ivory">
    <color rgba="1.0 0.945 0.773 1.0"/>
  </material>
  <material name="rh56_black">
    <color rgba="0.2 0.2 0.2 1.0"/>
  </material>
  <material name="rh56_gray">
    <color rgba="0.3 0.3 0.3 1.0"/>
  </material>
  <!-- Root link (was 'world') -->
  <link name="rh56_base_link"/>
  <!-- Base body link (was 'base_link') -->
  <link name="rh56_base_body_link">
    <visual>
      <geometry>
        <mesh filename="./meshes/robots/hdr35_20/visual/base_body.stl" scale="0.001 0.001 0.001"/>
      </geometry>
      <material name="rh56_ivory"/>
    </visual>
    <collision>
      <geometry>
        <mesh filename="./meshes/robots/hdr35_20/collision/base_body.stl" scale="0.001 0.001 0.001"/>
      </geometry>
    </collision>
    <inertial>
      <mass value="118.90"/>
      <origin rpy="0 0 0" xyz="0.0 0 0.1"/>
      <inertia ixx="2.7198" ixy="0.0" ixz="0.0" iyy="4.4954" iyz="0.0" izz="6.3413"/>
    </inertial>
  </link>
  <link name="rh56_lower_frame_link">
    <visual>
      <geometry>
        <mesh filename="./meshes/robots/hdr35_20/visual/lower_frame.stl" scale="0.001 0.001 0.001"/>
      </geometry>
      <material name="rh56_ivory"/>
    </visual>
    <collision>
      <geometry>
        <mesh filename="./meshes/robots/hdr35_20/collision/lower_frame.stl" scale="0.001 0.001 0.001"/>
      </geometry>
    </collision>
    <inertial>
      <mass value="147.17"/>
      <origin rpy="0 0 0" xyz="0.0 0 0.2"/>
      <inertia ixx="7.5400" ixy="0.0" ixz="0.0" iyy="8.1593" iyz="0.0" izz="6.2706"/>
    </inertial>
  </link>
  <link name="rh56_upper_frame_link">
    <visual>
      <geometry>
        <mesh filename="./meshes/robots/hdr35_20/visual/upper_frame.stl" scale="0.001 0.001 0.001"/>
      </geometry>
      <material name="rh56_ivory"/>
    </visual>
    <collision>
      <geometry>
        <mesh filename="./meshes/robots/hdr35_20/collision/upper_frame.stl" scale="0.001 0.001 0.001"/>
      </geometry>
    </collision>
    <inertial>
      <mass value="68.63"/>
      <origin rpy="0 0 0" xyz="0.0 0.0 -0.04"/>
      <inertia ixx="7.9244" ixy="0.0" ixz="0.0" iyy="0.7434" iyz="0.0" izz="8.2104"/>
    </inertial>
  </link>
  <link name="rh56_arm_link">
    <visual>
      <geometry>
        <mesh filename="./meshes/robots/hdr35_20/visual/arm.stl" scale="0.001 0.001 0.001"/>
      </geometry>
      <material name="rh56_ivory"/>
    </visual>
    <collision>
      <geometry>
        <mesh filename="./meshes/robots/hdr35_20/collision/arm.stl" scale="0.001 0.001 0.001"/>
      </geometry>
    </collision>
    <inertial>
      <mass value="73.93"/>
      <origin rpy="0 0 0" xyz="0 0 0"/>
      <inertia ixx="1.7700" ixy="0.0" ixz="0.0" iyy="6.6691" iyz="0.0" izz="7.1773"/>
    </inertial>
  </link>
  <link name="rh56_wrist_body_link">
    <visual>
      <geometry>
        <mesh filename="./meshes/robots/hdr35_20/visual/wrist_body.stl" scale="0.001 0.001 0.001"/>
      </geometry>
      <material name="rh56_ivory"/>
    </visual>
    <collision>
      <geometry>
        <mesh filename="./meshes/robots/hdr35_20/collision/wrist_body.stl" scale="0.001 0.001 0.001"/>
      </geometry>
    </collision>
    <inertial>
      <mass value="20.15"/>
      <origin rpy="0 0 0" xyz="0 0 0"/>
      <inertia ixx="0.0706" ixy="0.0" ixz="0.0" iyy="0.1553" iyz="0.0" izz="0.1601"/>
    </inertial>
  </link>
  <link name="rh56_wrist_holder_link">
    <visual>
      <geometry>
        <mesh filename="./meshes/robots/hdr35_20/visual/wrist_holder.stl" scale="0.001 0.001 0.001"/>
      </geometry>
      <material name="rh56_ivory"/>
    </visual>
    <collision>
      <geometry>
        <mesh filename="./meshes/robots/hdr35_20/collision/wrist_holder.stl" scale="0.001 0.001 0.001"/>
      </geometry>
    </collision>
    <inertial>
      <mass value="11.26"/>
      <origin rpy="0 0 0" xyz="0 0 0"/>
      <inertia ixx="0.0800" ixy="0.0" ixz="0.0" iyy="0.1130" iyz="0.0" izz="0.0938"/>
    </inertial>
  </link>
  <link name="rh56_flange_link">
    <visual>
      <origin rpy="0 0 0" xyz="0 0 0"/>
      <geometry>
        <mesh filename="./meshes/robots/hdr35_20/visual/flange.stl" scale="0.001 0.001 0.001"/>
      </geometry>
      <material name="rh56_gray"/>
    </visual>
    <collision>
      <origin rpy="0 0 0" xyz="0 0 0"/>
      <geometry>
        <mesh filename="./meshes/robots/hdr35_20/collision/flange.stl" scale="0.001 0.001 0.001"/>
      </geometry>
    </collision>
    <inertial>
      <mass value="0.79"/>
      <origin rpy="0 0 0" xyz="0.005 0 0"/>
      <inertia ixx="0.0022" ixy="0.0" ixz="0.0" iyy="0.0011" iyz="0.0" izz="0.0011"/>
    </inertial>
  </link>
  <!-- Joint connecting base_link to base_body_link -->
  <joint name="rh56_base_link-base_body_link" type="fixed">
    <origin rpy="0 0 0" xyz="0 0 0"/>
    <parent link="rh56_base_link"/>
    <child link="rh56_base_body_link"/>
  </joint>
  <joint name="rh56_j1" type="revolute">
    <parent link="rh56_base_body_link"/>
    <child link="rh56_lower_frame_link"/>
    <origin rpy="0 0 0" xyz="0 0 0"/>
    <axis xyz="0 0 1"/>
    <limit effort="3078.7" lower="-3.141" upper="3.141" velocity="3.141"/>
  </joint>
  <joint name="rh56_j2" type="revolute">
    <parent link="rh56_lower_frame_link"/>
    <child link="rh56_upper_frame_link"/>
    <origin rpy="1.5708 0 0" xyz="0.15 0.08 0.56"/>
    <axis xyz="0 0 1"/>
    <limit effort="3169.7" lower="-2.3558" upper="1.5702" velocity="3.141"/>
  </joint>
  <joint name="rh56_j3" type="revolute">
    <parent link="rh56_upper_frame_link"/>
    <child link="rh56_arm_link"/>
    <origin rpy="0 0 0" xyz="0 0.87 -0.04"/>
    <axis xyz="0 0 1"/>
    <limit effort="1507.0" lower="-1.396" upper="3.141" velocity="3.316"/>
  </joint>
  <joint name="rh56_j4" type="revolute">
    <parent link="rh56_arm_link"/>
    <child link="rh56_wrist_body_link"/>
    <origin rpy="0 0 0" xyz="0.828 0.175 0.1415"/>
    <axis xyz="1 0 0"/>
    <limit effort="259.0" lower="-6.283" upper="6.283" velocity="5.410"/>
  </joint>
  <joint name="rh56_j5" type="revolute">
    <parent link="rh56_wrist_body_link"/>
    <child link="rh56_wrist_holder_link"/>
    <origin rpy="0 0 0" xyz="0.195 0.0 0.04"/>
    <axis xyz="0 0 1"/>
    <limit effort="240.4" lower="-2.181" upper="2.181" velocity="5.410"/>
  </joint>
  <joint name="rh56_j6" type="revolute">
    <parent link="rh56_wrist_holder_link"/>
    <child link="rh56_flange_link"/>
    <origin rpy="-1.5708 0 0" xyz="0.175 0 -0.0375"/>
    <axis xyz="1 0 0"/>
    <limit effort="215.6" lower="-6.283" upper="6.283" velocity="7.330"/>
  </joint>
  <!-- Additional links for compatibility
      <link name="${prefix}flange"/>
      <joint name="${prefix}flange_link-flange" type="fixed">
        <origin rpy="0 0 0" xyz="0 0 0"/>
        <parent link="${prefix}flange_link"/>
        <child link="${prefix}flange"/>
      </joint>

      <link name="${prefix}tool0"/>
      <joint name="${prefix}flange-tool0" type="fixed">
        <origin rpy="0 1.5708 0" xyz="0 0 0"/>
        <parent link="${prefix}flange"/>
        <child link="${prefix}tool0"/>
      </joint> -->
  <!-- ====================== ATI FT SENSOR LINK ====================== -->
  <!-- Connect flange_link to ATI Axia80 FT Sensor -->
  <!-- Flange thickness: 5.1mm = 0.0051m -->
  <joint name="rh56_flange_ft_sensor" type="fixed">
    <origin rpy="0 0 0" xyz="0.0051 0 0"/>
    <parent link="rh56_flange_link"/>
    <child link="rh56_axia_80_ft_sensor"/>
  </joint>
  <link name="rh56_axia_80_ft_sensor">
    <visual>
      <origin rpy="0 0 0" xyz="0 0 0"/>
      <geometry>
        <mesh filename="./meshes/tools/ftsensor/Axia80M50.stl" scale="0.001 0.001 0.001"/>
      </geometry>
      <material name="rh56_gray"/>
    </visual>
    <collision>
      <origin rpy="0 0 0" xyz="0 0 0"/>
      <geometry>
        <mesh filename="./meshes/tools/ftsensor/Axia80M50.stl" scale="0.001 0.001 0.001"/>
      </geometry>
    </collision>
    <inertial>
      <mass value="0.28"/>
      <origin rpy="0 0 0" xyz="0.0127 0 0"/>
      <inertia ixx="0.00012" ixy="0.0" ixz="0.0" iyy="0.00012" iyz="0.0" izz="0.00024"/>
    </inertial>
  </link>
  <!-- ====================== FT SENSOR TO GRIPPER CONNECTION ====================== -->
  <!-- Connect ATI FT Sensor to RH56F1_R gripper_base_link -->
  <!-- FT Sensor thickness: 25.40mm = 0.0254m -->
  <!-- Apply tool0 transform (rpy="0 1.5708 0") for gripper orientation -->
  <joint name="rh56_force_sensor_joint" type="fixed">
    <origin rpy="0 1.5708 0" xyz="0.0254 0 0"/>
    <parent link="rh56_axia_80_ft_sensor"/>
    <child link="rh56_gripper_base_link"/>
  </joint>
  <link name="rh56_gripper_base_link">
    <inertial>
      <origin rpy="0 0 0" xyz="0.000631584180168987 1.55468476565051E-09 0.0185710308410627"/>
      <mass value="0.0793945003608915"/>
      <inertia ixx="2.73302869871105E-05" ixy="4.73396056660905E-13" ixz="2.86328005285174E-08" iyy="2.62165141408126E-05" iyz="1.90463743334758E-12" izz="3.5682432554866E-05"/>
    </inertial>
    <visual>
      <origin rpy="0 0 0" xyz="0 0 0"/>
      <geometry>
        <mesh filename="./meshes/tools/RH56F1_R/base_link.STL"/>
      </geometry>
      <material name="">
        <color rgba="1 1 1 1"/>
      </material>
    </visual>
    <collision>
      <origin rpy="0 0 0" xyz="0 0 0"/>
      <geometry>
        <mesh filename="./meshes/tools/RH56F1_R/base_link.STL"/>
      </geometry>
    </collision>
  </link>
  <link name="rh56_plam_1">
    <inertial>
      <origin rpy="0 0 0" xyz="-0.00132 0.00039 0.07415000000000001"/>
      <mass value="0.41238"/>
      <inertia ixx="0.00078835939" ixy="8.875e-07" ixz="3.202881e-05" iyy="0.00066648352" iyz="-1.4681199999999999e-06" izz="0.00026678122"/>
    </inertial>
    <visual>
      <origin rpy="0 0 0" xyz="0 0 0"/>
      <geometry>
        <mesh filename="./meshes/tools/RH56F1_R/plam_1.STL"/>
      </geometry>
      <material name="">
        <color rgba="0.866666666666667 0.866666666666667 0.890196078431372 1"/>
      </material>
    </visual>
    <collision>
      <origin rpy="0 0 0" xyz="0 0 0"/>
      <geometry>
        <mesh filename="./meshes/tools/RH56F1_R/plam_1.STL"/>
      </geometry>
    </collision>
  </link>
  <joint name="rh56_plam_1_joint" type="fixed">
    <origin rpy="0 0 0" xyz="0 0 0.0305"/>
    <parent link="rh56_gripper_base_link"/>
    <child link="rh56_plam_1"/>
    <axis xyz="0 0 0"/>
  </joint>
  <link name="rh56_plam_2">
    <inertial>
      <origin rpy="0 0 0" xyz="0.00780742986700294 -0.00181684242732992 0.0484726926194218"/>
      <mass value="0.01"/>
      <inertia ixx="7.53775883572448E-05" ixy="1.67198206435067E-06" ixz="-1.35138361804759E-06" iyy="4.62768852730386E-05" iyz="-3.66656859035162E-06" izz="3.55364070799627E-05"/>
    </inertial>
    <visual>
      <origin rpy="0 0 0" xyz="0 0 0"/>
      <geometry>
        <mesh filename="./meshes/tools/RH56F1_R/plam_2.STL"/>
      </geometry>
      <material name="">
        <color rgba="0.25 0.25 0.25 1"/>
      </material>
    </visual>
    <collision>
      <origin rpy="0 0 0" xyz="0 0 0"/>
      <geometry>
        <mesh filename="./meshes/tools/RH56F1_R/plam_2.STL"/>
      </geometry>
    </collision>
  </link>
  <joint name="rh56_plam_2_joint" type="fixed">
    <origin rpy="0 0 0" xyz="0 0 0"/>
    <parent link="rh56_plam_1"/>
    <child link="rh56_plam_2"/>
    <axis xyz="0 0 0"/>
  </joint>
  <link name="rh56_plam_3">
    <inertial>
      <origin rpy="0 0 0" xyz="-0.0145087315400233 0.00297298156011864 0.0599801851672911"/>
      <mass value="0.01"/>
      <inertia ixx="7.44229190374554E-05" ixy="-2.11457285174435E-06" ixz="3.53419391577662E-07" iyy="4.06574859268604E-05" iyz="3.15838633047347E-06" izz="4.24785219389853E-05"/>
    </inertial>
    <visual>
      <origin rpy="0 0 0" xyz="0 0 0"/>
      <geometry>
        <mesh filename="./meshes/tools/RH56F1_R/plam_3.STL"/>
      </geometry>
      <material name="">
        <color rgba="1 1 1 1"/>
      </material>
    </visual>
    <collision>
      <origin rpy="0 0 0" xyz="0 0 0"/>
      <geometry>
        <mesh filename="./meshes/tools/RH56F1_R/plam_3.STL"/>
      </geometry>
    </collision>
  </link>
  <joint name="rh56_plam_3_jont" type="fixed">
    <origin rpy="0 0 0" xyz="0 0 0"/>
    <parent link="rh56_plam_2"/>
    <child link="rh56_plam_3"/>
    <axis xyz="0 0 0"/>
  </joint>
  <link name="rh56_ee_link"/>
  <joint name="rh56_ee_joint" type="fixed">
    <parent link="rh56_plam_2"/>
    <child link="rh56_ee_link"/>
    <origin rpy="0 0 0" xyz="0.03 0 0.08"/>
  </joint>
  <link name="rh56_plam_force_sensor">
    <inertial>
      <origin rpy="0 0 0" xyz="0.00135015380328561 -0.00241176259562209 -0.00177409297911233"/>
      <mass value="0.00449423927061171"/>
      <inertia ixx="2.77343347350042E-07" ixy="-5.59517451189968E-13" ixz="2.86825536833881E-13" iyy="1.25942537762186E-06" iyz="5.96429255234865E-09" izz="1.53055908452317E-06"/>
    </inertial>
    <visual>
      <origin rpy="0 0 0" xyz="0 0 0"/>
      <geometry>
        <mesh filename="./meshes/tools/RH56F1_R/plam_force_sensor.STL"/>
      </geometry>
      <material name="">
        <color rgba="0.298039215686275 0.298039215686275 0.298039215686275 1"/>
      </material>
    </visual>
    <collision>
      <origin rpy="0 0 0" xyz="0 0 0"/>
      <geometry>
        <mesh filename="./meshes/tools/RH56F1_R/plam_force_sensor.STL"/>
      </geometry>
    </collision>
  </link>
  <joint name="rh56_plam_force_sensor_joint" type="fixed">
    <origin rpy="1.5707963267949 0 1.5707963267949" xyz="0.0159401947506102 -0.00135045394126701 0.0737460952299602"/>
    <parent link="rh56_plam_2"/>
    <child link="rh56_plam_force_sensor"/>
    <axis xyz="0 0 0"/>
  </joint>
  <link name="rh56_right_thumb_1">
    <inertial>
      <origin rpy="0 0 0" xyz="-0.00015 0.00544 -0.0048200000000000005"/>
      <mass value="0.016800000000000002"/>
      <inertia ixx="7.3387e-07" ixy="-1.436e-08" ixz="-1.11e-09" iyy="2.7925e-07" iyz="-3.296e-08" izz="5.8189e-07"/>
    </inertial>
    <visual>
      <origin rpy="0 0 0" xyz="0 0 0"/>
      <geometry>
        <mesh filename="./meshes/tools/RH56F1_R/right_thumb_1.STL"/>
      </geometry>
      <material name="">
        <color rgba="1 1 1 1"/>
      </material>
    </visual>
    <collision>
      <origin rpy="0 0 0" xyz="0 0 0"/>
      <geometry>
        <mesh filename="./meshes/tools/RH56F1_R/right_thumb_1.STL"/>
      </geometry>
    </collision>
  </link>
  <joint name="rh56_right_thumb_1_joint" type="revolute">
    <origin rpy="0 0 0" xyz="0.01836 0.027241 0.070511"/>
    <parent link="rh56_gripper_base_link"/>
    <child link="rh56_right_thumb_1"/>
    <axis xyz="8.7274E-05 0 -1"/>
    <limit effort="10" lower="0" upper="2.0943951023931953" velocity="3.0"/>
  </joint>
  <link name="rh56_right_thumb_2">
    <inertial>
      <origin rpy="0 0 0" xyz="-0.0238 0.01042 0.00478"/>
      <mass value="0.06526"/>
      <inertia ixx="1.378224e-05" ixy="5.95663e-06" ixz="-1.9799999999999998e-09" iyy="1.1840129999999999e-05" iyz="7.070000000000001e-09" izz="2.249189e-05"/>
    </inertial>
    <visual>
      <origin rpy="0 0 0" xyz="0 0 0"/>
      <geometry>
        <mesh filename="./meshes/tools/RH56F1_R/right_thumb_2.STL"/>
      </geometry>
      <material name="">
        <color rgba="0.25 0.25 0.25 1"/>
      </material>
    </visual>
    <collision>
      <origin rpy="0 0 0" xyz="0 0 0"/>
      <geometry>
        <mesh filename="./meshes/tools/RH56F1_R/right_thumb_2.STL"/>
      </geometry>
    </collision>
  </link>
  <joint name="rh56_right_thumb_2_joint" type="revolute">
    <origin rpy="1.5707 0 -1.5708" xyz="0.0047995 0.013396 -0.0052536"/>
    <parent link="rh56_right_thumb_1"/>
    <child link="rh56_right_thumb_2"/>
    <axis xyz="0 0 -1"/>
    <limit effort="10" lower="0" upper="0.4745550236172582" velocity="3.0"/>
  </joint>
  <link name="rh56_right_thumb_3">
    <inertial>
      <origin rpy="0 0 0" xyz="-0.01255 0.00331 0.00799"/>
      <mass value="0.01333"/>
      <inertia ixx="1.41987e-06" ixy="1.4979e-07" ixz="-6.3e-10" iyy="1.18482e-06" iyz="1.76e-09" izz="1.6920999999999999e-06"/>
    </inertial>
    <visual>
      <origin rpy="0 0 0" xyz="0 0 0"/>
      <geometry>
        <mesh filename="./meshes/tools/RH56F1_R/right_thumb_3.STL"/>
      </geometry>
      <material name="">
        <color rgba="0.25 0.25 0.25 1"/>
      </material>
    </visual>
    <collision>
      <origin rpy="0 0 0" xyz="0 0 0"/>
      <geometry>
        <mesh filename="./meshes/tools/RH56F1_R/right_thumb_3.STL"/>
      </geometry>
    </collision>
  </link>
  <joint name="rh56_right_thumb_3_joint" type="revolute">
    <origin rpy="0 0 0" xyz="-0.029155 0.03869 -0.0032"/>
    <parent link="rh56_right_thumb_2"/>
    <child link="rh56_right_thumb_3"/>
    <axis xyz="0 0 -1"/>
    <limit effort="10" lower="0" upper="3.14" velocity="5.0"/>
    <mimic joint="rh56_right_thumb_2_joint" multiplier="1.1425" offset="0"/>
  </joint>
  <link name="rh56_right_thumb_4">
    <inertial>
      <origin rpy="0 0 0" xyz="-0.010199999999999999 0.00886 0.0067"/>
      <mass value="0.011439999999999999"/>
      <inertia ixx="9.4221e-07" ixy="1.6288e-07" ixz="-0.0" iyy="3.9966e-07" iyz="-0.0" izz="9.478099999999999e-07"/>
    </inertial>
    <visual>
      <origin rpy="0 0 0" xyz="0 0 0"/>
      <geometry>
        <mesh filename="./meshes/tools/RH56F1_R/right_thumb_4.STL"/>
      </geometry>
      <material name="">
        <color rgba="0.25 0.25 0.25 1"/>
      </material>
    </visual>
    <collision>
      <origin rpy="0 0 0" xyz="0 0 0"/>
      <geometry>
        <mesh filename="./meshes/tools/RH56F1_R/right_thumb_4.STL"/>
      </geometry>
    </collision>
  </link>
  <joint name="rh56_right_thumb_4_joint" type="revolute">
    <origin rpy="0 0 0" xyz="-0.01441 0.014648 0.0013"/>
    <parent link="rh56_right_thumb_3"/>
    <child link="rh56_right_thumb_4"/>
    <axis xyz="0 0 -1"/>
    <limit effort="10" lower="0" upper="3.14" velocity="5.0"/>
    <mimic joint="rh56_right_thumb_3_joint" multiplier="0.7508" offset="0"/>
  </joint>
  <link name="rh56_thumb_force_sensor">
    <inertial>
      <origin rpy="0 0 0" xyz="0.0048965432924319 0.000707788830417878 -0.00883745365301308"/>
      <mass value="0"/>
      <inertia ixx="0" ixy="0" ixz="0" iyy="0" iyz="0" izz="0"/>
    </inertial>
    <visual>
      <origin rpy="0 0 0" xyz="0 0 0"/>
      <geometry>
        <mesh filename="./meshes/tools/RH56F1_R/thumb_force_sensor.STL"/>
      </geometry>
      <material name="">
        <color rgba="0.25 0.25 0.25 1"/>
      </material>
    </visual>
    <collision>
      <origin rpy="0 0 0" xyz="0 0 0"/>
      <geometry>
        <mesh filename="./meshes/tools/RH56F1_R/thumb_force_sensor.STL"/>
      </geometry>
    </collision>
  </link>
  <joint name="rh56_thumb_force_sensor_joint" type="fixed">
    <origin rpy="-1.6222 -0.051489 -0.78543" xyz="-0.0082761 0.019128 0.0068"/>
    <parent link="rh56_right_thumb_4"/>
    <child link="rh56_thumb_force_sensor"/>
    <axis xyz="0 0 0"/>
  </joint>
  <link name="rh56_thumb_tip">
    <inertial>
      <origin rpy="0 0 0" xyz="3.77562735170631E-05 -0.0101703967740828 -0.0136494381069971"/>
      <mass value="0"/>
      <inertia ixx="0" ixy="0" ixz="0" iyy="0" iyz="0" izz="0"/>
    </inertial>
    <visual>
      <origin rpy="0 0 0" xyz="0 0 0"/>
      <geometry>
        <mesh filename="./meshes/tools/RH56F1_R/thumb_tip.STL"/>
      </geometry>
      <material name="">
        <color rgba="0.25 0.25 0.25 1"/>
      </material>
    </visual>
    <collision>
      <origin rpy="0 0 0" xyz="0 0 0"/>
      <geometry>
        <mesh filename="./meshes/tools/RH56F1_R/thumb_tip.STL"/>
      </geometry>
    </collision>
  </link>
  <joint name="rh56_thumb_tip_joint" type="fixed">
    <origin rpy="-1.2971 1.5647 0.01425" xyz="-0.017405 0.025196 0.0068001"/>
    <parent link="rh56_right_thumb_4"/>
    <child link="rh56_thumb_tip"/>
    <axis xyz="0 0 0"/>
  </joint>
  <link name="rh56_right_index_1">
    <inertial>
      <origin rpy="0 0 0" xyz="0.00046 0.01509 0.0060999999999999995"/>
      <mass value="0.01111"/>
      <inertia ixx="2.04599e-06" ixy="-3.703e-08" ixz="1.77e-09" iyy="5.4029e-07" iyz="9.149e-08" izz="2.0895e-06"/>
    </inertial>
    <visual>
      <origin rpy="0 0 0" xyz="0 0 0"/>
      <geometry>
        <mesh filename="./meshes/tools/RH56F1_R/right_index_1.STL"/>
      </geometry>
      <material name="">
        <color rgba="0.25 0.25 0.25 1"/>
      </material>
    </visual>
    <collision>
      <origin rpy="0 0 0" xyz="0 0 0"/>
      <geometry>
        <mesh filename="./meshes/tools/RH56F1_R/right_index_1.STL"/>
      </geometry>
    </collision>
  </link>
  <joint name="rh56_right_index_1_joint" type="revolute">
    <origin rpy="1.5097 0 0" xyz="0.00070751 0.034376 0.13554"/>
    <parent link="rh56_gripper_base_link"/>
    <child link="rh56_right_index_1"/>
    <axis xyz="0 0 -1"/>
    <limit effort="10" lower="0" upper="1.5285593588966337" velocity="3.0"/>
  </joint>
  <link name="rh56_right_index_2">
    <inertial>
      <origin rpy="0 0 0" xyz="-0.00436 0.01623 0.005019999999999999"/>
      <mass value="0.0103"/>
      <inertia ixx="1.5669000000000002e-06" ixy="-2.2414e-07" ixz="1.3699999999999999e-08" iyy="2.9717e-07" iyz="7.84e-08" izz="1.5746300000000001e-06"/>
    </inertial>
    <visual>
      <origin rpy="0 0 0" xyz="0 0 0"/>
      <geometry>
        <mesh filename="./meshes/tools/RH56F1_R/right_index_2.STL"/>
      </geometry>
      <material name="">
        <color rgba="0.25 0.25 0.25 1"/>
      </material>
    </visual>
    <collision>
      <origin rpy="0 0 0" xyz="0 0 0"/>
      <geometry>
        <mesh filename="./meshes/tools/RH56F1_R/right_index_2.STL"/>
      </geometry>
    </collision>
  </link>
  <joint name="rh56_right_index_2_joint" type="revolute">
    <origin rpy="0 0 0" xyz="0.0031056 0.032854 0.001"/>
    <parent link="rh56_right_index_1"/>
    <child link="rh56_right_index_2"/>
    <axis xyz="0 0 -1"/>
    <limit effort="10" lower="0" upper="3.14" velocity="5.0"/>
    <mimic joint="rh56_right_index_1_joint" multiplier="1.1169" offset="0"/>
  </joint>
  <link name="rh56_index_force_sensor">
    <inertial>
      <origin rpy="0 0 0" xyz="-0.000411923019764227 -0.0123118470405642 -0.00640361541021662"/>
      <mass value="0"/>
      <inertia ixx="0" ixy="0" ixz="0" iyy="0" iyz="0" izz="0"/>
    </inertial>
    <visual>
      <origin rpy="0 0 0" xyz="0 0 0"/>
      <geometry>
        <mesh filename="./meshes/tools/RH56F1_R/index_force_sensor.STL"/>
      </geometry>
      <material name="">
        <color rgba="0.25 0.25 0.25 1"/>
      </material>
    </visual>
    <collision>
      <origin rpy="0 0 0" xyz="0 0 0"/>
      <geometry>
        <mesh filename="./meshes/tools/RH56F1_R/index_force_sensor.STL"/>
      </geometry>
    </collision>
  </link>
  <joint name="rh56_index_force_sensor_joint" type="fixed">
    <origin rpy="2.2782 1.4918 2.0953" xyz="0.005139 0.028671 0.0059996"/>
    <parent link="rh56_right_index_2"/>
    <child link="rh56_index_force_sensor"/>
    <axis xyz="0 0 0"/>
  </joint>
  <link name="rh56_index_tip">
    <inertial>
      <origin rpy="0 0 0" xyz="-0.00116882659469011 -0.0177404684378123 -0.0152714634926817"/>
      <mass value="0"/>
      <inertia ixx="0" ixy="0" ixz="0" iyy="0" iyz="0" izz="0"/>
    </inertial>
    <visual>
      <origin rpy="0 0 0" xyz="0 0 0"/>
      <geometry>
        <mesh filename="./meshes/tools/RH56F1_R/index_tip.STL"/>
      </geometry>
      <material name="">
        <color rgba="0.25 0.25 0.25 1"/>
      </material>
    </visual>
    <collision>
      <origin rpy="0 0 0" xyz="0 0 0"/>
      <geometry>
        <mesh filename="./meshes/tools/RH56F1_R/index_tip.STL"/>
      </geometry>
    </collision>
  </link>
  <joint name="rh56_index_tip_joint" type="fixed">
    <origin rpy="1.5446 1.5064 1.892" xyz="0.0049188 0.039631 0.006"/>
    <parent link="rh56_right_index_2"/>
    <child link="rh56_index_tip"/>
    <axis xyz="0 0 0"/>
  </joint>
  <link name="rh56_right_middle_1">
    <inertial>
      <origin rpy="0 0 0" xyz="0.00046 0.01468 0.00701"/>
      <mass value="0.01111"/>
      <inertia ixx="2.04599e-06" ixy="-3.707e-08" ixz="-4.9e-10" iyy="5.3491e-07" iyz="-3.6e-09" izz="2.09487e-06"/>
    </inertial>
    <visual>
      <origin rpy="0 0 0" xyz="0 0 0"/>
      <geometry>
        <mesh filename="./meshes/tools/RH56F1_R/right_middle_1.STL"/>
      </geometry>
      <material name="">
        <color rgba="0.25 0.25 0.25 1"/>
      </material>
    </visual>
    <collision>
      <origin rpy="0 0 0" xyz="0 0 0"/>
      <geometry>
        <mesh filename="./meshes/tools/RH56F1_R/right_middle_1.STL"/>
      </geometry>
    </collision>
  </link>
  <joint name="rh56_right_middle_1_joint" type="revolute">
    <origin rpy="1.5708 0 0" xyz="0.00070746 0.015767 0.13648"/>
    <parent link="rh56_gripper_base_link"/>
    <child link="rh56_right_middle_1"/>
    <axis xyz="0 0 -1"/>
    <limit effort="10" lower="0" upper="1.5285593588966337" velocity="3.0"/>
  </joint>
  <link name="rh56_right_middle_2">
    <inertial>
      <origin rpy="0 0 0" xyz="-0.004019999999999999 0.01731 0.006"/>
      <mass value="0.01122"/>
      <inertia ixx="1.92755e-06" ixy="-2.9305e-07" ixz="-1.0000000000000001e-11" iyy="3.2973000000000003e-07" iyz="-1.0000000000000001e-11" izz="1.95229e-06"/>
    </inertial>
    <visual>
      <origin rpy="0 0 0" xyz="0 0 0"/>
      <geometry>
        <mesh filename="./meshes/tools/RH56F1_R/right_middle_2.STL"/>
      </geometry>
      <material name="">
        <color rgba="0.25 0.25 0.25 1"/>
      </material>
    </visual>
    <collision>
      <origin rpy="0 0 0" xyz="0 0 0"/>
      <geometry>
        <mesh filename="./meshes/tools/RH56F1_R/right_middle_2.STL"/>
      </geometry>
    </collision>
  </link>
  <joint name="rh56_right_middle_2_joint" type="revolute">
    <origin rpy="0 0 0" xyz="0.0031056 0.032854 0.001"/>
    <parent link="rh56_right_middle_1"/>
    <child link="rh56_right_middle_2"/>
    <axis xyz="0 0 -1"/>
    <limit effort="10" lower="0" upper="3.14" velocity="5.0"/>
    <mimic joint="rh56_right_middle_1_joint" multiplier="1.1169" offset="0"/>
  </joint>
  <link name="rh56_middle_force_sensor">
    <inertial>
      <origin rpy="0 0 0" xyz="0.000471532938695406 -0.0138846665754712 -0.0063422335367961"/>
      <mass value="0"/>
      <inertia ixx="0" ixy="0" ixz="0" iyy="0" iyz="0" izz="0"/>
    </inertial>
    <visual>
      <origin rpy="0 0 0" xyz="0 0 0"/>
      <geometry>
        <mesh filename="./meshes/tools/RH56F1_R/middle_force_sensor.STL"/>
      </geometry>
      <material name="">
        <color rgba="0.25 0.25 0.25 1"/>
      </material>
    </visual>
    <collision>
      <origin rpy="0 0 0" xyz="0 0 0"/>
      <geometry>
        <mesh filename="./meshes/tools/RH56F1_R/middle_force_sensor.STL"/>
      </geometry>
    </collision>
  </link>
  <joint name="rh56_middle_force_sensor_joint" type="fixed">
    <origin rpy="-2.9405 1.5184 3.1416" xyz="0.0059655 0.031551 0.0060998"/>
    <parent link="rh56_right_middle_2"/>
    <child link="rh56_middle_force_sensor"/>
    <axis xyz="0 0 0"/>
  </joint>
  <link name="rh56_middle_tip">
    <inertial>
      <origin rpy="0 0 0" xyz="-1.56032137985686E-05 -0.0191696833676399 -0.0160122884402975"/>
      <mass value="0"/>
      <inertia ixx="0" ixy="0" ixz="0" iyy="0" iyz="0" izz="0"/>
    </inertial>
    <visual>
      <origin rpy="0 0 0" xyz="0 0 0"/>
      <geometry>
        <mesh filename="./meshes/tools/RH56F1_R/middle_tip.STL"/>
      </geometry>
      <material name="">
        <color rgba="0.25 0.25 0.25 1"/>
      </material>
    </visual>
    <collision>
      <origin rpy="0 0 0" xyz="0 0 0"/>
      <geometry>
        <mesh filename="./meshes/tools/RH56F1_R/middle_tip.STL"/>
      </geometry>
    </collision>
  </link>
  <joint name="rh56_middle_tip_joint" type="fixed">
    <origin rpy="-0.3273 1.5691 0" xyz="0.0059647 0.042512 0.0060998"/>
    <parent link="rh56_right_middle_2"/>
    <child link="rh56_middle_tip"/>
    <axis xyz="0 0 0"/>
  </joint>
  <link name="rh56_right_ring_1">
    <inertial>
      <origin rpy="0 0 0" xyz="0.00046 0.0143 0.00777"/>
      <mass value="0.01111"/>
      <inertia ixx="2.04599e-06" ixy="-3.699e-08" ixz="-2.43e-09" iyy="5.395599999999999e-07" iyz="-8.511e-08" izz="2.09023e-06"/>
    </inertial>
    <visual>
      <origin rpy="0 0 0" xyz="0 0 0"/>
      <geometry>
        <mesh filename="./meshes/tools/RH56F1_R/right_ring_1.STL"/>
      </geometry>
      <material name="">
        <color rgba="0.25 0.25 0.25 1"/>
      </material>
    </visual>
    <collision>
      <origin rpy="0 0 0" xyz="0 0 0"/>
      <geometry>
        <mesh filename="./meshes/tools/RH56F1_R/right_ring_1.STL"/>
      </geometry>
    </collision>
  </link>
  <joint name="rh56_right_ring_1_joint" type="revolute">
    <origin rpy="1.6232 0 0" xyz="0.00070746 -0.0030876 0.13643"/>
    <parent link="rh56_gripper_base_link"/>
    <child link="rh56_right_ring_1"/>
    <axis xyz="0 0 -1"/>
    <limit effort="10" lower="0" upper="1.5285593588966337" velocity="3.0"/>
  </joint>
  <link name="rh56_right_ring_2">
    <inertial>
      <origin rpy="0 0 0" xyz="-0.00436 0.015560000000000001 0.0068200000000000005"/>
      <mass value="0.0103"/>
      <inertia ixx="1.5669000000000002e-06" ixy="-2.2425e-07" ixz="-1.1759999999999999e-08" iyy="2.959e-07" iyz="-6.729e-08" izz="1.5758900000000002e-06"/>
    </inertial>
    <visual>
      <origin rpy="0 0 0" xyz="0 0 0"/>
      <geometry>
        <mesh filename="./meshes/tools/RH56F1_R/right_ring_2.STL"/>
      </geometry>
      <material name="">
        <color rgba="0.25 0.25 0.25 1"/>
      </material>
    </visual>
    <collision>
      <origin rpy="0 0 0" xyz="0 0 0"/>
      <geometry>
        <mesh filename="./meshes/tools/RH56F1_R/right_ring_2.STL"/>
      </geometry>
    </collision>
  </link>
  <joint name="rh56_right_ring_2_joint" type="revolute">
    <origin rpy="0 0 0" xyz="0.0031056 0.032854 0.001"/>
    <parent link="rh56_right_ring_1"/>
    <child link="rh56_right_ring_2"/>
    <axis xyz="0 0 -1"/>
    <limit effort="10" lower="0" upper="3.14" velocity="5.0"/>
    <mimic joint="rh56_right_ring_1_joint" multiplier="1.1169" offset="0"/>
  </joint>
  <link name="rh56_ring_force_sensor">
    <inertial>
      <origin rpy="0 0 0" xyz="0.00109767398054146 -0.0122697321740606 -0.00640361768517552"/>
      <mass value="0"/>
      <inertia ixx="0" ixy="0" ixz="0" iyy="0" iyz="0" izz="0"/>
    </inertial>
    <visual>
      <origin rpy="0 0 0" xyz="0 0 0"/>
      <geometry>
        <mesh filename="./meshes/tools/RH56F1_R/ring_force_sensor.STL"/>
      </geometry>
      <material name="">
        <color rgba="0.25 0.25 0.25 1"/>
      </material>
    </visual>
    <collision>
      <origin rpy="0 0 0" xyz="0 0 0"/>
      <geometry>
        <mesh filename="./meshes/tools/RH56F1_R/ring_force_sensor.STL"/>
      </geometry>
    </collision>
  </link>
  <joint name="rh56_ring_force_sensor_joint" type="fixed">
    <origin rpy="-2.2589 1.4899 -2.4386" xyz="0.005139 0.028671 0.0059996"/>
    <parent link="rh56_right_ring_2"/>
    <child link="rh56_ring_force_sensor"/>
    <axis xyz="0 0 0"/>
  </joint>
  <link name="rh56_ring_tip">
    <inertial>
      <origin rpy="0 0 0" xyz="0.000974578618407327 -0.0177521976538281 -0.015271465020787"/>
      <mass value="0"/>
      <inertia ixx="0" ixy="0" ixz="0" iyy="0" iyz="0" izz="0"/>
    </inertial>
    <visual>
      <origin rpy="0 0 0" xyz="0 0 0"/>
      <geometry>
        <mesh filename="./meshes/tools/RH56F1_R/ring_tip.STL"/>
      </geometry>
      <material name="">
        <color rgba="0.25 0.25 0.25 1"/>
      </material>
    </visual>
    <collision>
      <origin rpy="0 0 0" xyz="0 0 0"/>
      <geometry>
        <mesh filename="./meshes/tools/RH56F1_R/ring_tip.STL"/>
      </geometry>
    </collision>
  </link>
  <joint name="rh56_ring_tip_joint" type="fixed">
    <origin rpy="-1.5409 1.5145 -1.1936" xyz="0.0049188 0.039631 0.006"/>
    <parent link="rh56_right_ring_2"/>
    <child link="rh56_ring_tip"/>
    <axis xyz="0 0 0"/>
  </joint>
  <link name="rh56_right_little_1">
    <inertial>
      <origin rpy="0 0 0" xyz="0.00046 0.013869999999999999 0.0085"/>
      <mass value="0.01111"/>
      <inertia ixx="2.04599e-06" ixy="-3.6810000000000003e-08" ixz="-4.360000000000001e-09" iyy="5.527e-07" iyz="-1.6568e-07" izz="2.07708e-06"/>
    </inertial>
    <visual>
      <origin rpy="0 0 0" xyz="0 0 0"/>
      <geometry>
        <mesh filename="./meshes/tools/RH56F1_R/right_little_1.STL"/>
      </geometry>
      <material name="">
        <color rgba="0.25 0.25 0.25 1"/>
      </material>
    </visual>
    <collision>
      <origin rpy="0 0 0" xyz="0 0 0"/>
      <geometry>
        <mesh filename="./meshes/tools/RH56F1_R/right_little_1.STL"/>
      </geometry>
    </collision>
  </link>
  <joint name="rh56_right_little_1_joint" type="revolute">
    <origin rpy="1.6755 0 0" xyz="0.00070753 -0.021451 0.13527"/>
    <parent link="rh56_gripper_base_link"/>
    <child link="rh56_right_little_1"/>
    <axis xyz="0 0 -1"/>
    <limit effort="10" lower="0" upper="1.5285593588966337" velocity="3.0"/>
  </joint>
  <link name="rh56_right_little_2">
    <inertial>
      <origin rpy="0 0 0" xyz="-0.004070000000000001 0.01192 0.00728"/>
      <mass value="0.00839"/>
      <inertia ixx="9.3539e-07" ixy="-1.6843e-07" ixz="-1.7670000000000002e-08" iyy="2.4681e-07" iyz="-7.359e-08" izz="9.379400000000001e-07"/>
    </inertial>
    <visual>
      <origin rpy="0 0 0" xyz="0 0 0"/>
      <geometry>
        <mesh filename="./meshes/tools/RH56F1_R/right_little_2.STL"/>
      </geometry>
      <material name="">
        <color rgba="0.25 0.25 0.25 1"/>
      </material>
    </visual>
    <collision>
      <origin rpy="0 0 0" xyz="0 0 0"/>
      <geometry>
        <mesh filename="./meshes/tools/RH56F1_R/right_little_2.STL"/>
      </geometry>
    </collision>
  </link>
  <joint name="rh56_right_little_2_joint" type="revolute">
    <origin rpy="0 0 0" xyz="0.0031057 0.032854 0.001"/>
    <parent link="rh56_right_little_1"/>
    <child link="rh56_right_little_2"/>
    <axis xyz="0 0 -1"/>
    <limit effort="10" lower="0" upper="3.14" velocity="5.0"/>
    <mimic joint="rh56_right_little_1_joint" multiplier="1.1169" offset="0"/>
  </joint>
  <link name="rh56_little_force_sensor">
    <inertial>
      <origin rpy="0 0 0" xyz="0.00132747018137316 -0.00844356465788672 -0.00651118992676019"/>
      <mass value="0"/>
      <inertia ixx="0" ixy="0" ixz="0" iyy="0" iyz="0" izz="0"/>
    </inertial>
    <visual>
      <origin rpy="0 0 0" xyz="0 0 0"/>
      <geometry>
        <mesh filename="./meshes/tools/RH56F1_R/little_force_sensor.STL"/>
      </geometry>
      <material name="">
        <color rgba="0.25 0.25 0.25 1"/>
      </material>
    </visual>
    <collision>
      <origin rpy="0 0 0" xyz="0 0 0"/>
      <geometry>
        <mesh filename="./meshes/tools/RH56F1_R/little_force_sensor.STL"/>
      </geometry>
    </collision>
  </link>
  <joint name="rh56_little_force_sensor_joint" type="fixed">
    <origin rpy="-1.9859 1.443 -2.1833" xyz="0.0051314 0.021582 0.0059959"/>
    <parent link="rh56_right_little_2"/>
    <child link="rh56_little_force_sensor"/>
    <axis xyz="0 0 0"/>
  </joint>
  <link name="rh56_little_tip">
    <inertial>
      <origin rpy="0 0 0" xyz="0.00157850769633822 -0.0143797245335056 -0.0134611237924734"/>
      <mass value="0"/>
      <inertia ixx="0" ixy="0" ixz="0" iyy="0" iyz="0" izz="0"/>
    </inertial>
    <visual>
      <origin rpy="0 0 0" xyz="0 0 0"/>
      <geometry>
        <mesh filename="./meshes/tools/RH56F1_R/little_tip.STL"/>
      </geometry>
      <material name="">
        <color rgba="0.25 0.25 0.25 1"/>
      </material>
    </visual>
    <collision>
      <origin rpy="0 0 0" xyz="0 0 0"/>
      <geometry>
        <mesh filename="./meshes/tools/RH56F1_R/little_tip.STL"/>
      </geometry>
    </collision>
  </link>
  <joint name="rh56_little_tip_joint" type="fixed">
    <origin rpy="-1.5577 1.4597 -1.2296" xyz="0.0051203 0.032544 0.0059927"/>
    <parent link="rh56_right_little_2"/>
    <child link="rh56_little_tip"/>
    <axis xyz="0 0 0"/>
  </joint>
  <link name="rh56_index_tip1">
    <inertial>
      <origin rpy="0 0 0" xyz="0 0 0"/>
      <mass value="0.0001"/>
      <inertia ixx="1e-10" ixy="0" ixz="0" iyy="1e-10" iyz="0" izz="1e-10"/>
    </inertial>
    <visual>
      <geometry>
        <mesh filename="./meshes/tools/RH56F1_R/index_tip1.STL"/>
      </geometry>
    </visual>
  </link>
  <joint name="rh56_index_tip1_joint" type="fixed">
    <parent link="rh56_right_index_2"/>
    <child link="rh56_index_tip1"/>
    <origin rpy="-2.779205 1.570793 -3.139205" xyz="-0.003440 0.024370 0.005999"/>
  </joint>
  <link name="rh56_index_tip2">
    <inertial>
      <origin rpy="0 0 0" xyz="0 0 0"/>
      <mass value="0.0001"/>
      <inertia ixx="1e-10" ixy="0" ixz="0" iyy="1e-10" iyz="0" izz="1e-10"/>
    </inertial>
    <visual>
      <geometry>
        <mesh filename="./meshes/tools/RH56F1_R/index_tip2.STL"/>
      </geometry>
    </visual>
  </link>
  <joint name="rh56_index_tip2_joint" type="fixed">
    <parent link="rh56_right_index_2"/>
    <child link="rh56_index_tip2"/>
    <origin rpy="-2.779205 1.570793 -3.139205" xyz="-0.003440 0.024370 0.005999"/>
  </joint>
  <link name="rh56_index_tip3">
    <inertial>
      <origin rpy="0 0 0" xyz="0 0 0"/>
      <mass value="0.0001"/>
      <inertia ixx="1e-10" ixy="0" ixz="0" iyy="1e-10" iyz="0" izz="1e-10"/>
    </inertial>
    <visual>
      <geometry>
        <mesh filename="./meshes/tools/RH56F1_R/index_tip3.STL"/>
      </geometry>
    </visual>
  </link>
  <joint name="rh56_index_tip3_joint" type="fixed">
    <parent link="rh56_right_index_2"/>
    <child link="rh56_index_tip3"/>
    <origin rpy="-2.779205 1.570793 -3.139205" xyz="-0.003440 0.024370 0.005999"/>
  </joint>
  <link name="rh56_index_tip4">
    <inertial>
      <origin rpy="0 0 0" xyz="0 0 0"/>
      <mass value="0.0001"/>
      <inertia ixx="1e-10" ixy="0" ixz="0" iyy="1e-10" iyz="0" izz="1e-10"/>
    </inertial>
    <visual>
      <geometry>
        <mesh filename="./meshes/tools/RH56F1_R/index_tip4.STL"/>
      </geometry>
    </visual>
  </link>
  <joint name="rh56_index_tip4_joint" type="fixed">
    <parent link="rh56_right_index_2"/>
    <child link="rh56_index_tip4"/>
    <origin rpy="-2.779205 1.570793 -3.139205" xyz="-0.003440 0.024370 0.005999"/>
  </joint>
  <link name="rh56_index_tip5">
    <inertial>
      <origin rpy="0 0 0" xyz="0 0 0"/>
      <mass value="0.0001"/>
      <inertia ixx="1e-10" ixy="0" ixz="0" iyy="1e-10" iyz="0" izz="1e-10"/>
    </inertial>
    <visual>
      <geometry>
        <mesh filename="./meshes/tools/RH56F1_R/index_tip5.STL"/>
      </geometry>
    </visual>
  </link>
  <joint name="rh56_index_tip5_joint" type="fixed">
    <parent link="rh56_right_index_2"/>
    <child link="rh56_index_tip5"/>
    <origin rpy="-2.779205 1.570793 -3.139205" xyz="-0.003440 0.024370 0.005999"/>
  </joint>
  <link name="rh56_middle_tip1">
    <inertial>
      <origin rpy="0 0 0" xyz="0 0 0"/>
      <mass value="0.0001"/>
      <inertia ixx="1e-10" ixy="0" ixz="0" iyy="1e-10" iyz="0" izz="1e-10"/>
    </inertial>
    <visual>
      <geometry>
        <mesh filename="./meshes/tools/RH56F1_R/middle_tip1.STL"/>
      </geometry>
    </visual>
  </link>
  <joint name="rh56_middle_tip1_joint" type="fixed">
    <parent link="rh56_right_middle_2"/>
    <child link="rh56_middle_tip1"/>
    <origin rpy="-2.766614 1.570793 -3.140914" xyz="-0.002660 0.027440 0.006100"/>
  </joint>
  <link name="rh56_middle_tip2">
    <inertial>
      <origin rpy="0 0 0" xyz="0 0 0"/>
      <mass value="0.0001"/>
      <inertia ixx="1e-10" ixy="0" ixz="0" iyy="1e-10" iyz="0" izz="1e-10"/>
    </inertial>
    <visual>
      <geometry>
        <mesh filename="./meshes/tools/RH56F1_R/middle_tip2.STL"/>
      </geometry>
    </visual>
  </link>
  <joint name="rh56_middle_tip2_joint" type="fixed">
    <parent link="rh56_right_middle_2"/>
    <child link="rh56_middle_tip2"/>
    <origin rpy="-2.766614 1.570793 -3.140914" xyz="-0.002660 0.027440 0.006100"/>
  </joint>
  <link name="rh56_middle_tip3">
    <inertial>
      <origin rpy="0 0 0" xyz="0 0 0"/>
      <mass value="0.0001"/>
      <inertia ixx="1e-10" ixy="0" ixz="0" iyy="1e-10" iyz="0" izz="1e-10"/>
    </inertial>
    <visual>
      <geometry>
        <mesh filename="./meshes/tools/RH56F1_R/middle_tip3.STL"/>
      </geometry>
    </visual>
  </link>
  <joint name="rh56_middle_tip3_joint" type="fixed">
    <parent link="rh56_right_middle_2"/>
    <child link="rh56_middle_tip3"/>
    <origin rpy="-2.766614 1.570793 -3.140914" xyz="-0.002660 0.027440 0.006100"/>
  </joint>
  <link name="rh56_middle_tip4">
    <inertial>
      <origin rpy="0 0 0" xyz="0 0 0"/>
      <mass value="0.0001"/>
      <inertia ixx="1e-10" ixy="0" ixz="0" iyy="1e-10" iyz="0" izz="1e-10"/>
    </inertial>
    <visual>
      <geometry>
        <mesh filename="./meshes/tools/RH56F1_R/middle_tip4.STL"/>
      </geometry>
    </visual>
  </link>
  <joint name="rh56_middle_tip4_joint" type="fixed">
    <parent link="rh56_right_middle_2"/>
    <child link="rh56_middle_tip4"/>
    <origin rpy="-2.766614 1.570793 -3.140914" xyz="-0.002660 0.027440 0.006100"/>
  </joint>
  <link name="rh56_middle_tip5">
    <inertial>
      <origin rpy="0 0 0" xyz="0 0 0"/>
      <mass value="0.0001"/>
      <inertia ixx="1e-10" ixy="0" ixz="0" iyy="1e-10" iyz="0" izz="1e-10"/>
    </inertial>
    <visual>
      <geometry>
        <mesh filename="./meshes/tools/RH56F1_R/middle_tip5.STL"/>
      </geometry>
    </visual>
  </link>
  <joint name="rh56_middle_tip5_joint" type="fixed">
    <parent link="rh56_right_middle_2"/>
    <child link="rh56_middle_tip5"/>
    <origin rpy="-2.766614 1.570793 -3.140914" xyz="-0.002660 0.027440 0.006100"/>
  </joint>
  <link name="rh56_ring_tip1">
    <inertial>
      <origin rpy="0 0 0" xyz="0 0 0"/>
      <mass value="0.0001"/>
      <inertia ixx="1e-10" ixy="0" ixz="0" iyy="1e-10" iyz="0" izz="1e-10"/>
    </inertial>
    <visual>
      <geometry>
        <mesh filename="./meshes/tools/RH56F1_R/ring_tip1.STL"/>
      </geometry>
    </visual>
  </link>
  <joint name="rh56_ring_tip1_joint" type="fixed">
    <parent link="rh56_right_ring_2"/>
    <child link="rh56_ring_tip1"/>
    <origin rpy="-2.785214 1.570793 -3.141214" xyz="-0.003425 0.024363 0.006000"/>
  </joint>
  <link name="rh56_ring_tip2">
    <inertial>
      <origin rpy="0 0 0" xyz="0 0 0"/>
      <mass value="0.0001"/>
      <inertia ixx="1e-10" ixy="0" ixz="0" iyy="1e-10" iyz="0" izz="1e-10"/>
    </inertial>
    <visual>
      <geometry>
        <mesh filename="./meshes/tools/RH56F1_R/ring_tip2.STL"/>
      </geometry>
    </visual>
  </link>
  <joint name="rh56_ring_tip2_joint" type="fixed">
    <parent link="rh56_right_ring_2"/>
    <child link="rh56_ring_tip2"/>
    <origin rpy="-2.785214 1.570793 -3.141214" xyz="-0.003425 0.024363 0.006000"/>
  </joint>
  <link name="rh56_ring_tip3">
    <inertial>
      <origin rpy="0 0 0" xyz="0 0 0"/>
      <mass value="0.0001"/>
      <inertia ixx="1e-10" ixy="0" ixz="0" iyy="1e-10" iyz="0" izz="1e-10"/>
    </inertial>
    <visual>
      <geometry>
        <mesh filename="./meshes/tools/RH56F1_R/ring_tip3.STL"/>
      </geometry>
    </visual>
  </link>
  <joint name="rh56_ring_tip3_joint" type="fixed">
    <parent link="rh56_right_ring_2"/>
    <child link="rh56_ring_tip3"/>
    <origin rpy="-2.785214 1.570793 -3.141214" xyz="-0.003425 0.024363 0.006000"/>
  </joint>
  <link name="rh56_ring_tip4">
    <inertial>
      <origin rpy="0 0 0" xyz="0 0 0"/>
      <mass value="0.0001"/>
      <inertia ixx="1e-10" ixy="0" ixz="0" iyy="1e-10" iyz="0" izz="1e-10"/>
    </inertial>
    <visual>
      <geometry>
        <mesh filename="./meshes/tools/RH56F1_R/ring_tip4.STL"/>
      </geometry>
    </visual>
  </link>
  <joint name="rh56_ring_tip4_joint" type="fixed">
    <parent link="rh56_right_ring_2"/>
    <child link="rh56_ring_tip4"/>
    <origin rpy="-2.785214 1.570793 -3.141214" xyz="-0.003425 0.024363 0.006000"/>
  </joint>
  <link name="rh56_ring_tip5">
    <inertial>
      <origin rpy="0 0 0" xyz="0 0 0"/>
      <mass value="0.0001"/>
      <inertia ixx="1e-10" ixy="0" ixz="0" iyy="1e-10" iyz="0" izz="1e-10"/>
    </inertial>
    <visual>
      <geometry>
        <mesh filename="./meshes/tools/RH56F1_R/ring_tip5.STL"/>
      </geometry>
    </visual>
  </link>
  <joint name="rh56_ring_tip5_joint" type="fixed">
    <parent link="rh56_right_ring_2"/>
    <child link="rh56_ring_tip5"/>
    <origin rpy="-2.785214 1.570793 -3.141214" xyz="-0.003425 0.024363 0.006000"/>
  </joint>
  <link name="rh56_little_tip1">
    <inertial>
      <origin rpy="0 0 0" xyz="0 0 0"/>
      <mass value="0.0001"/>
      <inertia ixx="1e-10" ixy="0" ixz="0" iyy="1e-10" iyz="0" izz="1e-10"/>
    </inertial>
    <visual>
      <geometry>
        <mesh filename="./meshes/tools/RH56F1_R/little_tip1.STL"/>
      </geometry>
    </visual>
  </link>
  <joint name="rh56_little_tip1_joint" type="fixed">
    <parent link="rh56_right_little_2"/>
    <child link="rh56_little_tip1"/>
    <origin rpy="-2.743284 1.570793 -3.116284" xyz="-0.003500 0.017453 0.005995"/>
  </joint>
  <link name="rh56_little_tip2">
    <inertial>
      <origin rpy="0 0 0" xyz="0 0 0"/>
      <mass value="0.0001"/>
      <inertia ixx="1e-10" ixy="0" ixz="0" iyy="1e-10" iyz="0" izz="1e-10"/>
    </inertial>
    <visual>
      <geometry>
        <mesh filename="./meshes/tools/RH56F1_R/little_tip2.STL"/>
      </geometry>
    </visual>
  </link>
  <joint name="rh56_little_tip2_joint" type="fixed">
    <parent link="rh56_right_little_2"/>
    <child link="rh56_little_tip2"/>
    <origin rpy="-2.743284 1.570793 -3.116284" xyz="-0.003500 0.017453 0.005995"/>
  </joint>
  <link name="rh56_little_tip3">
    <inertial>
      <origin rpy="0 0 0" xyz="0 0 0"/>
      <mass value="0.0001"/>
      <inertia ixx="1e-10" ixy="0" ixz="0" iyy="1e-10" iyz="0" izz="1e-10"/>
    </inertial>
    <visual>
      <geometry>
        <mesh filename="./meshes/tools/RH56F1_R/little_tip3.STL"/>
      </geometry>
    </visual>
  </link>
  <joint name="rh56_little_tip3_joint" type="fixed">
    <parent link="rh56_right_little_2"/>
    <child link="rh56_little_tip3"/>
    <origin rpy="-2.743284 1.570793 -3.116284" xyz="-0.003500 0.017453 0.005995"/>
  </joint>
  <link name="rh56_little_tip4">
    <inertial>
      <origin rpy="0 0 0" xyz="0 0 0"/>
      <mass value="0.0001"/>
      <inertia ixx="1e-10" ixy="0" ixz="0" iyy="1e-10" iyz="0" izz="1e-10"/>
    </inertial>
    <visual>
      <geometry>
        <mesh filename="./meshes/tools/RH56F1_R/little_tip4.STL"/>
      </geometry>
    </visual>
  </link>
  <joint name="rh56_little_tip4_joint" type="fixed">
    <parent link="rh56_right_little_2"/>
    <child link="rh56_little_tip4"/>
    <origin rpy="-2.743284 1.570793 -3.116284" xyz="-0.003500 0.017453 0.005995"/>
  </joint>
  <link name="rh56_little_tip5">
    <inertial>
      <origin rpy="0 0 0" xyz="0 0 0"/>
      <mass value="0.0001"/>
      <inertia ixx="1e-10" ixy="0" ixz="0" iyy="1e-10" iyz="0" izz="1e-10"/>
    </inertial>
    <visual>
      <geometry>
        <mesh filename="./meshes/tools/RH56F1_R/little_tip5.STL"/>
      </geometry>
    </visual>
  </link>
  <joint name="rh56_little_tip5_joint" type="fixed">
    <parent link="rh56_right_little_2"/>
    <child link="rh56_little_tip5"/>
    <origin rpy="-2.743284 1.570793 -3.116284" xyz="-0.003500 0.017453 0.005995"/>
  </joint>
  <link name="rh56_thumb_tip1">
    <inertial>
      <origin rpy="0 0 0" xyz="0 0 0"/>
      <mass value="0.0001"/>
      <inertia ixx="1e-10" ixy="0" ixz="0" iyy="1e-10" iyz="0" izz="1e-10"/>
    </inertial>
    <visual>
      <geometry>
        <mesh filename="./meshes/tools/RH56F1_R/thumb_tip1.STL"/>
      </geometry>
    </visual>
  </link>
  <joint name="rh56_thumb_tip1_joint" type="fixed">
    <parent link="rh56_right_thumb_4"/>
    <child link="rh56_thumb_tip1"/>
    <origin rpy="2.518066 1.570793 3.126066" xyz="-0.009500 0.009640 0.006800"/>
  </joint>
  <link name="rh56_thumb_tip2">
    <inertial>
      <origin rpy="0 0 0" xyz="0 0 0"/>
      <mass value="0.0001"/>
      <inertia ixx="1e-10" ixy="0" ixz="0" iyy="1e-10" iyz="0" izz="1e-10"/>
    </inertial>
    <visual>
      <geometry>
        <mesh filename="./meshes/tools/RH56F1_R/thumb_tip2.STL"/>
      </geometry>
    </visual>
  </link>
  <joint name="rh56_thumb_tip2_joint" type="fixed">
    <parent link="rh56_right_thumb_4"/>
    <child link="rh56_thumb_tip2"/>
    <origin rpy="2.518066 1.570793 3.126066" xyz="-0.009500 0.009640 0.006800"/>
  </joint>
  <link name="rh56_thumb_tip3">
    <inertial>
      <origin rpy="0 0 0" xyz="0 0 0"/>
      <mass value="0.0001"/>
      <inertia ixx="1e-10" ixy="0" ixz="0" iyy="1e-10" iyz="0" izz="1e-10"/>
    </inertial>
    <visual>
      <geometry>
        <mesh filename="./meshes/tools/RH56F1_R/thumb_tip3.STL"/>
      </geometry>
    </visual>
  </link>
  <joint name="rh56_thumb_tip3_joint" type="fixed">
    <parent link="rh56_right_thumb_4"/>
    <child link="rh56_thumb_tip3"/>
    <origin rpy="2.518066 1.570793 3.126066" xyz="-0.009500 0.009640 0.006800"/>
  </joint>
  <link name="rh56_thumb_tip4">
    <inertial>
      <origin rpy="0 0 0" xyz="0 0 0"/>
      <mass value="0.0001"/>
      <inertia ixx="1e-10" ixy="0" ixz="0" iyy="1e-10" iyz="0" izz="1e-10"/>
    </inertial>
    <visual>
      <geometry>
        <mesh filename="./meshes/tools/RH56F1_R/thumb_tip4.STL"/>
      </geometry>
    </visual>
  </link>
  <joint name="rh56_thumb_tip4_joint" type="fixed">
    <parent link="rh56_right_thumb_4"/>
    <child link="rh56_thumb_tip4"/>
    <origin rpy="2.518066 1.570793 3.126066" xyz="-0.009500 0.009640 0.006800"/>
  </joint>
  <link name="rh56_thumb_tip5">
    <inertial>
      <origin rpy="0 0 0" xyz="0 0 0"/>
      <mass value="0.0001"/>
      <inertia ixx="1e-10" ixy="0" ixz="0" iyy="1e-10" iyz="0" izz="1e-10"/>
    </inertial>
    <visual>
      <geometry>
        <mesh filename="./meshes/tools/RH56F1_R/thumb_tip5.STL"/>
      </geometry>
    </visual>
  </link>
  <joint name="rh56_thumb_tip5_joint" type="fixed">
    <parent link="rh56_right_thumb_4"/>
    <child link="rh56_thumb_tip5"/>
    <origin rpy="2.518066 1.570793 3.126066" xyz="-0.009500 0.009640 0.006800"/>
  </joint>
  <!-- =================================================================================== -->
  <!-- Modified for cuRobo usage -->
  <!-- - Changed world link to base_link (root link) -->
  <!-- - Removed base link (renamed to base_body_link) -->
  <!-- - Removed motor links (motor_s, motor_h, motor_v) -->
  <!-- - Changed mesh paths to relative paths -->
  <!-- =================================================================================== -->
  <material name="dg5f_ivory">
    <color rgba="1.0 0.945 0.773 1.0"/>
  </material>
  <material name="dg5f_black">
    <color rgba="0.2 0.2 0.2 1.0"/>
  </material>
  <material name="dg5f_gray">
    <color rgba="0.3 0.3 0.3 1.0"/>
  </material>
  <!-- Root link (was 'world') -->
  <link name="dg5f_base_link"/>
  <!-- Base body link (was 'base_link') -->
  <link name="dg5f_base_body_link">
    <visual>
      <geometry>
        <mesh filename="./meshes/robots/hdr35_20/visual/base_body.stl" scale="0.001 0.001 0.001"/>
      </geometry>
      <material name="dg5f_ivory"/>
    </visual>
    <collision>
      <geometry>
        <mesh filename="./meshes/robots/hdr35_20/collision/base_body.stl" scale="0.001 0.001 0.001"/>
      </geometry>
    </collision>
    <inertial>
      <mass value="118.90"/>
      <origin rpy="0 0 0" xyz="0.0 0 0.1"/>
      <inertia ixx="2.7198" ixy="0.0" ixz="0.0" iyy="4.4954" iyz="0.0" izz="6.3413"/>
    </inertial>
  </link>
  <link name="dg5f_lower_frame_link">
    <visual>
      <geometry>
        <mesh filename="./meshes/robots/hdr35_20/visual/lower_frame.stl" scale="0.001 0.001 0.001"/>
      </geometry>
      <material name="dg5f_ivory"/>
    </visual>
    <collision>
      <geometry>
        <mesh filename="./meshes/robots/hdr35_20/collision/lower_frame.stl" scale="0.001 0.001 0.001"/>
      </geometry>
    </collision>
    <inertial>
      <mass value="147.17"/>
      <origin rpy="0 0 0" xyz="0.0 0 0.2"/>
      <inertia ixx="7.5400" ixy="0.0" ixz="0.0" iyy="8.1593" iyz="0.0" izz="6.2706"/>
    </inertial>
  </link>
  <link name="dg5f_upper_frame_link">
    <visual>
      <geometry>
        <mesh filename="./meshes/robots/hdr35_20/visual/upper_frame.stl" scale="0.001 0.001 0.001"/>
      </geometry>
      <material name="dg5f_ivory"/>
    </visual>
    <collision>
      <geometry>
        <mesh filename="./meshes/robots/hdr35_20/collision/upper_frame.stl" scale="0.001 0.001 0.001"/>
      </geometry>
    </collision>
    <inertial>
      <mass value="68.63"/>
      <origin rpy="0 0 0" xyz="0.0 0.0 -0.04"/>
      <inertia ixx="7.9244" ixy="0.0" ixz="0.0" iyy="0.7434" iyz="0.0" izz="8.2104"/>
    </inertial>
  </link>
  <link name="dg5f_arm_link">
    <visual>
      <geometry>
        <mesh filename="./meshes/robots/hdr35_20/visual/arm.stl" scale="0.001 0.001 0.001"/>
      </geometry>
      <material name="dg5f_ivory"/>
    </visual>
    <collision>
      <geometry>
        <mesh filename="./meshes/robots/hdr35_20/collision/arm.stl" scale="0.001 0.001 0.001"/>
      </geometry>
    </collision>
    <inertial>
      <mass value="73.93"/>
      <origin rpy="0 0 0" xyz="0 0 0"/>
      <inertia ixx="1.7700" ixy="0.0" ixz="0.0" iyy="6.6691" iyz="0.0" izz="7.1773"/>
    </inertial>
  </link>
  <link name="dg5f_wrist_body_link">
    <visual>
      <geometry>
        <mesh filename="./meshes/robots/hdr35_20/visual/wrist_body.stl" scale="0.001 0.001 0.001"/>
      </geometry>
      <material name="dg5f_ivory"/>
    </visual>
    <collision>
      <geometry>
        <mesh filename="./meshes/robots/hdr35_20/collision/wrist_body.stl" scale="0.001 0.001 0.001"/>
      </geometry>
    </collision>
    <inertial>
      <mass value="20.15"/>
      <origin rpy="0 0 0" xyz="0 0 0"/>
      <inertia ixx="0.0706" ixy="0.0" ixz="0.0" iyy="0.1553" iyz="0.0" izz="0.1601"/>
    </inertial>
  </link>
  <link name="dg5f_wrist_holder_link">
    <visual>
      <geometry>
        <mesh filename="./meshes/robots/hdr35_20/visual/wrist_holder.stl" scale="0.001 0.001 0.001"/>
      </geometry>
      <material name="dg5f_ivory"/>
    </visual>
    <collision>
      <geometry>
        <mesh filename="./meshes/robots/hdr35_20/collision/wrist_holder.stl" scale="0.001 0.001 0.001"/>
      </geometry>
    </collision>
    <inertial>
      <mass value="11.26"/>
      <origin rpy="0 0 0" xyz="0 0 0"/>
      <inertia ixx="0.0800" ixy="0.0" ixz="0.0" iyy="0.1130" iyz="0.0" izz="0.0938"/>
    </inertial>
  </link>
  <link name="dg5f_flange_link">
    <visual>
      <origin rpy="0 0 0" xyz="0 0 0"/>
      <geometry>
        <mesh filename="./meshes/robots/hdr35_20/visual/flange.stl" scale="0.001 0.001 0.001"/>
      </geometry>
      <material name="dg5f_gray"/>
    </visual>
    <collision>
      <origin rpy="0 0 0" xyz="0 0 0"/>
      <geometry>
        <mesh filename="./meshes/robots/hdr35_20/collision/flange.stl" scale="0.001 0.001 0.001"/>
      </geometry>
    </collision>
    <inertial>
      <mass value="0.79"/>
      <origin rpy="0 0 0" xyz="0.005 0 0"/>
      <inertia ixx="0.0022" ixy="0.0" ixz="0.0" iyy="0.0011" iyz="0.0" izz="0.0011"/>
    </inertial>
  </link>
  <!-- Joint connecting base_link to base_body_link -->
  <joint name="dg5f_base_link-base_body_link" type="fixed">
    <origin rpy="0 0 0" xyz="0 0 0"/>
    <parent link="dg5f_base_link"/>
    <child link="dg5f_base_body_link"/>
  </joint>
  <joint name="dg5f_j1" type="revolute">
    <parent link="dg5f_base_body_link"/>
    <child link="dg5f_lower_frame_link"/>
    <origin rpy="0 0 0" xyz="0 0 0"/>
    <axis xyz="0 0 1"/>
    <limit effort="3078.7" lower="-3.141" upper="3.141" velocity="3.141"/>
  </joint>
  <joint name="dg5f_j2" type="revolute">
    <parent link="dg5f_lower_frame_link"/>
    <child link="dg5f_upper_frame_link"/>
    <origin rpy="1.5708 0 0" xyz="0.15 0.08 0.56"/>
    <axis xyz="0 0 1"/>
    <limit effort="3169.7" lower="-2.3558" upper="1.5702" velocity="3.141"/>
  </joint>
  <joint name="dg5f_j3" type="revolute">
    <parent link="dg5f_upper_frame_link"/>
    <child link="dg5f_arm_link"/>
    <origin rpy="0 0 0" xyz="0 0.87 -0.04"/>
    <axis xyz="0 0 1"/>
    <limit effort="1507.0" lower="-1.396" upper="3.141" velocity="3.316"/>
  </joint>
  <joint name="dg5f_j4" type="revolute">
    <parent link="dg5f_arm_link"/>
    <child link="dg5f_wrist_body_link"/>
    <origin rpy="0 0 0" xyz="0.828 0.175 0.1415"/>
    <axis xyz="1 0 0"/>
    <limit effort="259.0" lower="-6.283" upper="6.283" velocity="5.410"/>
  </joint>
  <joint name="dg5f_j5" type="revolute">
    <parent link="dg5f_wrist_body_link"/>
    <child link="dg5f_wrist_holder_link"/>
    <origin rpy="0 0 0" xyz="0.195 0.0 0.04"/>
    <axis xyz="0 0 1"/>
    <limit effort="240.4" lower="-2.181" upper="2.181" velocity="5.410"/>
  </joint>
  <joint name="dg5f_j6" type="revolute">
    <parent link="dg5f_wrist_holder_link"/>
    <child link="dg5f_flange_link"/>
    <origin rpy="-1.5708 0 0" xyz="0.175 0 -0.0375"/>
    <axis xyz="1 0 0"/>
    <limit effort="215.6" lower="-6.283" upper="6.283" velocity="7.330"/>
  </joint>
  <!-- Additional links for compatibility
      <link name="${prefix}flange"/>
      <joint name="${prefix}flange_link-flange" type="fixed">
        <origin rpy="0 0 0" xyz="0 0 0"/>
        <parent link="${prefix}flange_link"/>
        <child link="${prefix}flange"/>
      </joint>

      <link name="${prefix}tool0"/>
      <joint name="${prefix}flange-tool0" type="fixed">
        <origin rpy="0 1.5708 0" xyz="0 0 0"/>
        <parent link="${prefix}flange"/>
        <child link="${prefix}tool0"/>
      </joint> -->
  <!-- ====================== ATI FT SENSOR LINK ====================== -->
  <!-- Connect flange_link to ATI Axia80 FT Sensor -->
  <!-- Flange thickness: 5.1mm = 0.0051m -->
  <joint name="dg5f_flange_ft_sensor" type="fixed">
    <origin rpy="0 0 0" xyz="0.0051 0 0"/>
    <parent link="dg5f_flange_link"/>
    <child link="dg5f_axia_80_ft_sensor"/>
  </joint>
  <link name="dg5f_axia_80_ft_sensor">
    <visual>
      <origin rpy="0 0 0" xyz="0 0 0"/>
      <geometry>
        <mesh filename="./meshes/tools/ftsensor/Axia80M50.stl" scale="0.001 0.001 0.001"/>
      </geometry>
      <material name="dg5f_gray"/>
    </visual>
    <collision>
      <origin rpy="0 0 0" xyz="0 0 0"/>
      <geometry>
        <mesh filename="./meshes/tools/ftsensor/Axia80M50.stl" scale="0.001 0.001 0.001"/>
      </geometry>
    </collision>
    <inertial>
      <mass value="0.28"/>
      <origin rpy="0 0 0" xyz="0.0127 0 0"/>
      <inertia ixx="0.00012" ixy="0.0" ixz="0.0" iyy="0.00012" iyz="0.0" izz="0.00024"/>
    </inertial>
  </link>
  <!-- ====================== FT SENSOR TO GRIPPER CONNECTION ====================== -->
  <!-- Connect ATI FT Sensor to RH56F1_R gripper_base_link -->
  <!-- FT Sensor thickness: 25.40mm = 0.0254m -->
  <!-- Apply tool0 transform (rpy="0 1.5708 0") for gripper orientation -->
  <joint name="dg5f_force_sensor_joint" type="fixed">
    <origin rpy="0 1.5708 0" xyz="0.0254 0 0"/>
    <parent link="dg5f_axia_80_ft_sensor"/>
    <child link="dg5f_gripper_base_link"/>
  </joint>
  <!--
        dg5f_left.urdf
        Licensed under the BSD-3-Clause
        Copyright (c) 2025 Tesollo Inc.
        See LICENSE file for details.

        Reference:
        * https://tesollo.com/dg-5f/
    -->
  <link name="dg5f_gripper_base_link">
    <inertial>
      <origin rpy="0.0 0.0 0.0" xyz="6.4721E-09 2.1674E-05 0.0049997"/>
      <inertia ixx="1.0999E-05" ixy="-2.1734E-12" ixz="-1.2441E-12" iyy="1.1018E-05" iyz="-4.0435E-09" izz="2.0531E-05"/>
      <mass value="0.05"/>
    </inertial>
    <visual>
      <geometry>
        <mesh filename="./meshes/tools/dg5f_left/visual/ll_dg_mount.dae"/>
      </geometry>
    </visual>
    <collision>
      <geometry>
        <mesh filename="./meshes/tools/dg5f_left/collision/ll_dg_mount_c.STL"/>
      </geometry>
    </collision>
  </link>
  <link name="dg5f_ll_dg_base">
    <inertial>
      <origin rpy="0.0 0.0 0.0" xyz="-0.00058969 -0.00051381 0.037363"/>
      <inertia ixx="0.00048608" ixy="-1.041E-05" ixz="1.7229E-05" iyy="0.00049085" iyz="5.191E-06" izz="0.00043369"/>
      <mass value="0.45"/>
    </inertial>
    <visual>
      <origin rpy="0 0 0" xyz="0 0 0"/>
      <geometry>
        <mesh filename="./meshes/tools/dg5f_left/visual/ll_dg_base.dae"/>
      </geometry>
    </visual>
    <collision>
      <origin rpy="0 0 0" xyz="0 0 0"/>
      <geometry>
        <mesh filename="./meshes/tools/dg5f_left/collision/ll_dg_base_c.STL"/>
      </geometry>
    </collision>
  </link>
  <joint name="dg5f_lj_dg_base" type="fixed">
    <parent link="dg5f_gripper_base_link"/>
    <child link="dg5f_ll_dg_base"/>
    <origin rpy="0 0 0" xyz="0 0 0.004"/>
  </joint>
  <link name="dg5f_ll_dg_palm">
    <inertial>
      <origin rpy="0.0 0.0 0.0" xyz="-0.0089544 -0.00095674 0.041327"/>
      <inertia ixx="0.00052648" ixy="-2.618E-06" ixz="-2.2256E-05" iyy="0.00041644" iyz="4.8923E-05" izz="0.00045776"/>
      <mass value="0.35"/>
    </inertial>
    <visual>
      <origin rpy="0 0 0" xyz="0 0 0"/>
      <geometry>
        <mesh filename="./meshes/tools/dg5f_left/visual/ll_dg_palm.dae"/>
      </geometry>
    </visual>
    <collision>
      <origin rpy="0 0 0" xyz="0 0 0"/>
      <geometry>
        <mesh filename="./meshes/tools/dg5f_left/collision/ll_dg_palm_c.STL"/>
      </geometry>
    </collision>
  </link>
  <joint name="dg5f_lj_dg_palm" type="fixed">
    <parent link="dg5f_ll_dg_base"/>
    <child link="dg5f_ll_dg_palm"/>
    <origin rpy="0 0 0" xyz="0 0 0.0698"/>
  </joint>
  <link name="dg5f_ee_link"/>
  <joint name="dg5f_ee_joint" type="fixed">
    <parent link="dg5f_ll_dg_palm"/>
    <child link="dg5f_ee_link"/>
    <origin rpy="0 0 0" xyz="0.03 0 0.08"/>
  </joint>
  <link name="dg5f_ll_dg_1_1">
    <inertial>
      <origin rpy="0.0 0.0 0.0" xyz="0.021473 3.1163E-06 0.0028146"/>
      <inertia ixx="4.2707E-06" ixy="2.4123E-09" ixz="2.9055E-06" iyy="1.3718E-05" iyz="-1.3824E-09" izz="1.2161E-05"/>
      <mass value="0.045"/>
    </inertial>
    <visual>
      <origin rpy="0 0 0" xyz="0 0 0"/>
      <geometry>
        <mesh filename="./meshes/tools/dg5f_left/visual/ll_dg_1_1.dae"/>
      </geometry>
    </visual>
    <collision>
      <origin rpy="0 0 0" xyz="0 0 0"/>
      <geometry>
        <mesh filename="./meshes/tools/dg5f_left/collision/ll_dg_1_1_c.STL"/>
      </geometry>
    </collision>
  </link>
  <joint name="dg5f_lj_dg_1_1" type="revolute">
    <origin rpy="0.0 0.0 0.0" xyz="-0.0162 -0.019 0.0128"/>
    <parent link="dg5f_ll_dg_palm"/>
    <child link="dg5f_ll_dg_1_1"/>
    <axis xyz="1 0 0"/>
    <limit effort="7.5" lower="-0.8901179185171081" upper="0.3839724354387525" velocity="3.141592653589793"/>
  </joint>
  <link name="dg5f_ll_dg_1_2">
    <inertial>
      <origin rpy="0.0 0.0 0.0" xyz="-0.00055633 -0.0155 0.00055633"/>
      <inertia ixx="1.9935E-06" ixy="-1.5774E-07" ixz="-3.114E-09" iyy="1.459E-06" iyz="-1.5774E-07" izz="1.9935E-06"/>
      <mass value="0.025"/>
    </inertial>
    <visual>
      <origin rpy="0 0 0" xyz="0 0 0"/>
      <geometry>
        <mesh filename="./meshes/tools/dg5f_left/visual/ll_dg_1_2.dae"/>
      </geometry>
    </visual>
    <collision>
      <origin rpy="0 0 0" xyz="0 0 0"/>
      <geometry>
        <mesh filename="./meshes/tools/dg5f_left/collision/ll_dg_1_2_c.STL"/>
      </geometry>
    </collision>
  </link>
  <joint name="dg5f_lj_dg_1_2" type="revolute">
    <origin rpy="0.0 0.0 0.0" xyz="0.04195 0.0 0.0"/>
    <parent link="dg5f_ll_dg_1_1"/>
    <child link="dg5f_ll_dg_1_2"/>
    <axis xyz="0 0 1"/>
    <limit effort="7.5" lower="-0.0" upper="3.141592653589793" velocity="3.141592653589793"/>
  </joint>
  <link name="dg5f_ll_dg_1_3">
    <inertial>
      <origin rpy="0.0 0.0 0.0" xyz="-2.3008E-05 -0.014842 4.7446E-06"/>
      <inertia ixx="5.9794E-06" ixy="-3.6014E-07" ixz="1.3678E-09" iyy="2.458E-06" iyz="2.3552E-09" izz="6.4181E-06"/>
      <mass value="0.045"/>
    </inertial>
    <visual>
      <origin rpy="0 0 0" xyz="0 0 0"/>
      <geometry>
        <mesh filename="./meshes/tools/dg5f_left/visual/ll_dg_1_3.dae"/>
      </geometry>
    </visual>
    <collision>
      <origin rpy="0 0 0" xyz="0 0 0"/>
      <geometry>
        <mesh filename="./meshes/tools/dg5f_left/collision/ll_dg_1_3_c.STL"/>
      </geometry>
    </collision>
  </link>
  <joint name="dg5f_lj_dg_1_3" type="revolute">
    <origin rpy="0.0 0.0 0.0" xyz="0.0 -0.031 0.0"/>
    <parent link="dg5f_ll_dg_1_2"/>
    <child link="dg5f_ll_dg_1_3"/>
    <axis xyz="1 0 0"/>
    <limit effort="7.5" lower="-1.5707963267948966" upper="1.5707963267948966" velocity="3.141592653589793"/>
  </joint>
  <link name="dg5f_ll_dg_1_4">
    <inertial>
      <origin rpy="0.0 0.0 0.0" xyz="0.00020482 -0.018795 -0.00036539"/>
      <inertia ixx="9.4915E-06" ixy="-1.5157E-07" ixz="-3.4626E-09" iyy="2.9391E-06" iyz="-3.7813E-07" izz="9.8194E-06"/>
      <mass value="0.045"/>
    </inertial>
    <visual>
      <origin rpy="0 0 0" xyz="0 0 0"/>
      <geometry>
        <mesh filename="./meshes/tools/dg5f_left/visual/ll_dg_1_4.dae"/>
      </geometry>
    </visual>
    <collision>
      <origin rpy="0 0 0" xyz="0 0 0"/>
      <geometry>
        <mesh filename="./meshes/tools/dg5f_left/collision/ll_dg_1_4_c.STL"/>
      </geometry>
    </collision>
  </link>
  <joint name="dg5f_lj_dg_1_4" type="revolute">
    <origin rpy="0.0 0.0 0.0" xyz="0.0 -0.0388 0.0"/>
    <parent link="dg5f_ll_dg_1_3"/>
    <child link="dg5f_ll_dg_1_4"/>
    <axis xyz="1 0 0"/>
    <limit effort="7.5" lower="-1.5707963267948966" upper="1.5707963267948966" velocity="3.141592653589793"/>
  </joint>
  <link name="dg5f_ll_dg_1_tip">
    <inertial>
      <origin rpy="0.0 0.0 0.0" xyz="-5.479E-07 -0.007157 0.0038063"/>
      <inertia ixx="1.9895E-07" ixy="-3.0731E-11" ixz="-2.1191E-12" iyy="2.5698E-07" iyz="-1.3375E-08" izz="3.2445E-07"/>
      <mass value="0.005"/>
    </inertial>
    <visual>
      <origin rpy="0 0 0" xyz="0 0 0"/>
      <geometry>
        <mesh filename="./meshes/tools/dg5f_left/visual/ll_dg_1_tip.dae"/>
      </geometry>
    </visual>
    <collision>
      <origin rpy="0 0 0" xyz="0 0 0"/>
      <geometry>
        <mesh filename="./meshes/tools/dg5f_left/collision/ll_dg_1_tip_c.STL"/>
      </geometry>
    </collision>
  </link>
  <joint name="dg5f_lj_dg_1_tip" type="fixed">
    <origin rpy="0.0 0.0 0.0" xyz="0.0 -0.0363 0.0"/>
    <parent link="dg5f_ll_dg_1_4"/>
    <child link="dg5f_ll_dg_1_tip"/>
  </joint>
  <link name="dg5f_ll_dg_2_1">
    <inertial>
      <origin rpy="0.0 0.0 0.0" xyz="0.0010606 -0.00058566 0.023499"/>
      <inertia ixx="6.5541E-06" ixy="1.8684E-07" ixz="-1.1508E-06" iyy="9.5306E-06" iyz="-5.3298E-09" izz="7.0879E-06"/>
      <mass value="0.045"/>
    </inertial>
    <visual>
      <origin rpy="0 0 0" xyz="0 0 0"/>
      <geometry>
        <mesh filename="./meshes/tools/dg5f_left/visual/ll_dg_2_1.dae"/>
      </geometry>
    </visual>
    <collision>
      <origin rpy="0 0 0" xyz="0 0 0"/>
      <geometry>
        <mesh filename="./meshes/tools/dg5f_left/collision/ll_dg_2_1_c.STL"/>
      </geometry>
    </collision>
  </link>
  <joint name="dg5f_lj_dg_2_1" type="revolute">
    <origin rpy="0.0 0.0 0.0" xyz="-0.0071 -0.027 0.0661"/>
    <parent link="dg5f_ll_dg_palm"/>
    <child link="dg5f_ll_dg_2_1"/>
    <axis xyz="1 0 0"/>
    <limit effort="7.5" lower="-0.6108652381980153" upper="0.4188790204786391" velocity="3.141592653589793"/>
  </joint>
  <link name="dg5f_ll_dg_2_2">
    <inertial>
      <origin rpy="0.0 0.0 0.0" xyz="-4.7446E-06 2.3008E-05 0.023958"/>
      <inertia ixx="6.4181E-06" ixy="1.3678E-09" ixz="-2.3552E-09" iyy="5.9794E-06" iyz="3.6014E-07" izz="2.458E-06"/>
      <mass value="0.045"/>
    </inertial>
    <visual>
      <origin rpy="0 0 0" xyz="0 0 0"/>
      <geometry>
        <mesh filename="./meshes/tools/dg5f_left/visual/ll_dg_2_2.dae"/>
      </geometry>
    </visual>
    <collision>
      <origin rpy="0 0 0" xyz="0 0 0"/>
      <geometry>
        <mesh filename="./meshes/tools/dg5f_left/collision/ll_dg_2_2_c.STL"/>
      </geometry>
    </collision>
  </link>
  <joint name="dg5f_lj_dg_2_2" type="revolute">
    <origin rpy="0.0 0.0 0.0" xyz="0.01765 0.0 0.0265"/>
    <parent link="dg5f_ll_dg_2_1"/>
    <child link="dg5f_ll_dg_2_2"/>
    <axis xyz="0 1 0"/>
    <limit effort="7.5" lower="-0.0" upper="2.007128639793479" velocity="3.141592653589793"/>
  </joint>
  <link name="dg5f_ll_dg_2_3">
    <inertial>
      <origin rpy="0.0 0.0 0.0" xyz="-4.7446E-06 2.3008E-05 0.023958"/>
      <inertia ixx="6.4181E-06" ixy="1.3678E-09" ixz="-2.3552E-09" iyy="5.9794E-06" iyz="3.6014E-07" izz="2.458E-06"/>
      <mass value="0.045"/>
    </inertial>
    <visual>
      <origin rpy="0 0 0" xyz="0 0 0"/>
      <geometry>
        <mesh filename="./meshes/tools/dg5f_left/visual/ll_dg_2_3.dae"/>
      </geometry>
    </visual>
    <collision>
      <origin rpy="0 0 0" xyz="0 0 0"/>
      <geometry>
        <mesh filename="./meshes/tools/dg5f_left/collision/ll_dg_2_3_c.STL"/>
      </geometry>
    </collision>
  </link>
  <joint name="dg5f_lj_dg_2_3" type="revolute">
    <origin rpy="0.0 0.0 0.0" xyz="0.0 0.0 0.0388"/>
    <parent link="dg5f_ll_dg_2_2"/>
    <child link="dg5f_ll_dg_2_3"/>
    <axis xyz="0 1 0"/>
    <limit effort="7.5" lower="-1.5707963267948966" upper="1.5707963267948966" velocity="3.141592653589793"/>
  </joint>
  <link name="dg5f_ll_dg_2_4">
    <inertial>
      <origin rpy="0.0 0.0 0.0" xyz="-0.00070816 0.00043036 0.017842"/>
      <inertia ixx="2.8592E-06" ixy="-5.9306E-09" ixz="2.1028E-07" iyy="2.3907E-06" iyz="1.8286E-07" izz="1.6592E-06"/>
      <mass value="0.025"/>
    </inertial>
    <visual>
      <origin rpy="0 0 0" xyz="0 0 0"/>
      <geometry>
        <mesh filename="./meshes/tools/dg5f_left/visual/ll_dg_2_4.dae"/>
      </geometry>
    </visual>
    <collision>
      <origin rpy="0 0 0" xyz="0 0 0"/>
      <geometry>
        <mesh filename="./meshes/tools/dg5f_left/collision/ll_dg_2_4_c.STL"/>
      </geometry>
    </collision>
  </link>
  <joint name="dg5f_lj_dg_2_4" type="revolute">
    <origin rpy="0.0 0.0 0.0" xyz="0.0 0.0 0.0388"/>
    <parent link="dg5f_ll_dg_2_3"/>
    <child link="dg5f_ll_dg_2_4"/>
    <axis xyz="0 1 0"/>
    <limit effort="7.5" lower="-1.5707963267948966" upper="1.5707963267948966" velocity="3.141592653589793"/>
  </joint>
  <link name="dg5f_ll_dg_2_tip">
    <inertial>
      <origin rpy="0.0 0.0 0.0" xyz="0.0038063 5.479E-07 0.007157"/>
      <inertia ixx="3.2445E-07" ixy="2.1191E-12" ixz="1.3375E-08" iyy="1.9895E-07" iyz="-3.0731E-11" izz="2.5698E-07"/>
      <mass value="0.005"/>
    </inertial>
    <visual>
      <origin rpy="0 0 0" xyz="0 0 0"/>
      <geometry>
        <mesh filename="./meshes/tools/dg5f_left/visual/ll_dg_2_tip.dae"/>
      </geometry>
    </visual>
    <collision>
      <origin rpy="0 0 0" xyz="0 0 0"/>
      <geometry>
        <mesh filename="./meshes/tools/dg5f_left/collision/ll_dg_2_tip_c.STL"/>
      </geometry>
    </collision>
  </link>
  <joint name="dg5f_lj_dg_2_tip" type="fixed">
    <origin rpy="0.0 0.0 0.0" xyz="0.0 0.0 0.0255"/>
    <parent link="dg5f_ll_dg_2_4"/>
    <child link="dg5f_ll_dg_2_tip"/>
  </joint>
  <link name="dg5f_ll_dg_3_1">
    <inertial>
      <origin rpy="0.0 0.0 0.0" xyz="0.0012558 -0.00017703 0.023374"/>
      <inertia ixx="6.233E-06" ixy="1.1315E-07" ixz="-1.1589E-06" iyy="9.3331E-06" iyz="3.5383E-08" izz="6.7817E-06"/>
      <mass value="0.045"/>
    </inertial>
    <visual>
      <origin rpy="0 0 0" xyz="0 0 0"/>
      <geometry>
        <mesh filename="./meshes/tools/dg5f_left/visual/ll_dg_3_1.dae"/>
      </geometry>
    </visual>
    <collision>
      <origin rpy="0 0 0" xyz="0 0 0"/>
      <geometry>
        <mesh filename="./meshes/tools/dg5f_left/collision/ll_dg_3_1_c.STL"/>
      </geometry>
    </collision>
  </link>
  <joint name="dg5f_lj_dg_3_1" type="revolute">
    <origin rpy="0.0 0.0 0.0" xyz="-0.0071 -0.0025 0.0701"/>
    <parent link="dg5f_ll_dg_palm"/>
    <child link="dg5f_ll_dg_3_1"/>
    <axis xyz="1 0 0"/>
    <limit effort="7.5" lower="-0.6108652381980153" upper="0.6108652381980153" velocity="3.141592653589793"/>
  </joint>
  <link name="dg5f_ll_dg_3_2">
    <inertial>
      <origin rpy="0.0 0.0 0.0" xyz="-4.7446E-06 2.3008E-05 0.023958"/>
      <inertia ixx="6.4181E-06" ixy="1.3678E-09" ixz="-2.3552E-09" iyy="5.9794E-06" iyz="3.6014E-07" izz="2.458E-06"/>
      <mass value="0.045"/>
    </inertial>
    <visual>
      <origin rpy="0 0 0" xyz="0 0 0"/>
      <geometry>
        <mesh filename="./meshes/tools/dg5f_left/visual/ll_dg_3_2.dae"/>
      </geometry>
    </visual>
    <collision>
      <origin rpy="0 0 0" xyz="0 0 0"/>
      <geometry>
        <mesh filename="./meshes/tools/dg5f_left/collision/ll_dg_3_2_c.STL"/>
      </geometry>
    </collision>
  </link>
  <joint name="dg5f_lj_dg_3_2" type="revolute">
    <origin rpy="0.0 0.0 0.0" xyz="0.01765 0.0 0.0265"/>
    <parent link="dg5f_ll_dg_3_1"/>
    <child link="dg5f_ll_dg_3_2"/>
    <axis xyz="0 1 0"/>
    <limit effort="7.5" lower="0.0" upper="1.9547687622336491" velocity="3.141592653589793"/>
  </joint>
  <link name="dg5f_ll_dg_3_3">
    <inertial>
      <origin rpy="0.0 0.0 0.0" xyz="-4.7446E-06 2.3008E-05 0.023958"/>
      <inertia ixx="6.4181E-06" ixy="1.3678E-09" ixz="-2.3552E-09" iyy="5.9794E-06" iyz="3.6014E-07" izz="2.458E-06"/>
      <mass value="0.045"/>
    </inertial>
    <visual>
      <origin rpy="0 0 0" xyz="0 0 0"/>
      <geometry>
        <mesh filename="./meshes/tools/dg5f_left/visual/ll_dg_3_3.dae"/>
      </geometry>
    </visual>
    <collision>
      <origin rpy="0 0 0" xyz="0 0 0"/>
      <geometry>
        <mesh filename="./meshes/tools/dg5f_left/collision/ll_dg_3_3_c.STL"/>
      </geometry>
    </collision>
  </link>
  <joint name="dg5f_lj_dg_3_3" type="revolute">
    <origin rpy="0.0 0.0 0.0" xyz="0.0 0.0 0.0388"/>
    <parent link="dg5f_ll_dg_3_2"/>
    <child link="dg5f_ll_dg_3_3"/>
    <axis xyz="0 1 0"/>
    <limit effort="7.5" lower="-1.5707963267948966" upper="1.5707963267948966" velocity="3.141592653589793"/>
  </joint>
  <link name="dg5f_ll_dg_3_4">
    <inertial>
      <origin rpy="0.0 0.0 0.0" xyz="-0.00070816 0.00043036 0.017842"/>
      <inertia ixx="2.8592E-06" ixy="-5.9306E-09" ixz="2.1028E-07" iyy="2.3907E-06" iyz="1.8286E-07" izz="1.6592E-06"/>
      <mass value="0.025"/>
    </inertial>
    <visual>
      <origin rpy="0 0 0" xyz="0 0 0"/>
      <geometry>
        <mesh filename="./meshes/tools/dg5f_left/visual/ll_dg_3_4.dae"/>
      </geometry>
    </visual>
    <collision>
      <origin rpy="0 0 0" xyz="0 0 0"/>
      <geometry>
        <mesh filename="./meshes/tools/dg5f_left/collision/ll_dg_3_4_c.STL"/>
      </geometry>
    </collision>
  </link>
  <joint name="dg5f_lj_dg_3_4" type="revolute">
    <origin rpy="0.0 0.0 0.0" xyz="0.0 0.0 0.0388"/>
    <parent link="dg5f_ll_dg_3_3"/>
    <child link="dg5f_ll_dg_3_4"/>
    <axis xyz="0 1 0"/>
    <limit effort="7.5" lower="-1.5707963267948966" upper="1.5707963267948966" velocity="3.141592653589793"/>
  </joint>
  <link name="dg5f_ll_dg_3_tip">
    <inertial>
      <origin rpy="0.0 0.0 0.0" xyz="0.0038063 5.479E-07 0.007157"/>
      <inertia ixx="3.2445E-07" ixy="2.1191E-12" ixz="1.3375E-08" iyy="1.9895E-07" iyz="-3.0731E-11" izz="2.5698E-07"/>
      <mass value="0.005"/>
    </inertial>
    <visual>
      <origin rpy="0 0 0" xyz="0 0 0"/>
      <geometry>
        <mesh filename="./meshes/tools/dg5f_left/visual/ll_dg_3_tip.dae"/>
      </geometry>
    </visual>
    <collision>
      <origin rpy="0 0 0" xyz="0 0 0"/>
      <geometry>
        <mesh filename="./meshes/tools/dg5f_left/collision/ll_dg_3_tip_c.STL"/>
      </geometry>
    </collision>
  </link>
  <joint name="dg5f_lj_dg_3_tip" type="fixed">
    <origin rpy="0.0 0.0 0.0" xyz="0.0 0.0 0.0255"/>
    <parent link="dg5f_ll_dg_3_4"/>
    <child link="dg5f_ll_dg_3_tip"/>
  </joint>
  <link name="dg5f_ll_dg_4_1">
    <inertial>
      <origin rpy="0.0 0.0 0.0" xyz="0.001061 0.00024417 0.023499"/>
      <inertia ixx="6.5538E-06" ixy="3.9294E-08" ixz="-1.1507E-06" iyy="9.5305E-06" iyz="7.6072E-08" izz="7.0877E-06"/>
      <mass value="0.045"/>
    </inertial>
    <visual>
      <origin rpy="0 0 0" xyz="0 0 0"/>
      <geometry>
        <mesh filename="./meshes/tools/dg5f_left/visual/ll_dg_4_1.dae"/>
      </geometry>
    </visual>
    <collision>
      <origin rpy="0 0 0" xyz="0 0 0"/>
      <geometry>
        <mesh filename="./meshes/tools/dg5f_left/collision/ll_dg_4_1_c.STL"/>
      </geometry>
    </collision>
  </link>
  <joint name="dg5f_lj_dg_4_1" type="revolute">
    <origin rpy="0.0 0.0 0.0" xyz="-0.0071 0.022 0.0621"/>
    <parent link="dg5f_ll_dg_palm"/>
    <child link="dg5f_ll_dg_4_1"/>
    <axis xyz="1 0 0"/>
    <limit effort="7.5" lower="-0.4188790204786391" upper="0.6108652381980153" velocity="3.141592653589793"/>
  </joint>
  <link name="dg5f_ll_dg_4_2">
    <inertial>
      <origin rpy="0.0 0.0 0.0" xyz="-4.7446E-06 2.3008E-05 0.023958"/>
      <inertia ixx="6.4181E-06" ixy="1.3678E-09" ixz="-2.3552E-09" iyy="5.9794E-06" iyz="3.6014E-07" izz="2.458E-06"/>
      <mass value="0.045"/>
    </inertial>
    <visual>
      <origin rpy="0 0 0" xyz="0 0 0"/>
      <geometry>
        <mesh filename="./meshes/tools/dg5f_left/visual/ll_dg_4_2.dae"/>
      </geometry>
    </visual>
    <collision>
      <origin rpy="0 0 0" xyz="0 0 0"/>
      <geometry>
        <mesh filename="./meshes/tools/dg5f_left/collision/ll_dg_4_2_c.STL"/>
      </geometry>
    </collision>
  </link>
  <joint name="dg5f_lj_dg_4_2" type="revolute">
    <origin rpy="0.0 0.0 0.0" xyz="0.01765 0.0 0.0265"/>
    <parent link="dg5f_ll_dg_4_1"/>
    <child link="dg5f_ll_dg_4_2"/>
    <axis xyz="0 1 0"/>
    <limit effort="7.5" lower="0.0" upper="1.9024088846738192" velocity="3.141592653589793"/>
  </joint>
  <link name="dg5f_ll_dg_4_3">
    <inertial>
      <origin rpy="0.0 0.0 0.0" xyz="-4.7446E-06 2.3008E-05 0.023958"/>
      <inertia ixx="6.4181E-06" ixy="1.3678E-09" ixz="-2.3552E-09" iyy="5.9794E-06" iyz="3.6014E-07" izz="2.458E-06"/>
      <mass value="0.045"/>
    </inertial>
    <visual>
      <origin rpy="0 0 0" xyz="0 0 0"/>
      <geometry>
        <mesh filename="./meshes/tools/dg5f_left/visual/ll_dg_4_3.dae"/>
      </geometry>
    </visual>
    <collision>
      <origin rpy="0 0 0" xyz="0 0 0"/>
      <geometry>
        <mesh filename="./meshes/tools/dg5f_left/collision/ll_dg_4_3_c.STL"/>
      </geometry>
    </collision>
  </link>
  <joint name="dg5f_lj_dg_4_3" type="revolute">
    <origin rpy="0.0 0.0 0.0" xyz="0.0 0.0 0.0388"/>
    <parent link="dg5f_ll_dg_4_2"/>
    <child link="dg5f_ll_dg_4_3"/>
    <axis xyz="0 1 0"/>
    <limit effort="7.5" lower="-1.5707963267948966" upper="1.5707963267948966" velocity="3.141592653589793"/>
  </joint>
  <link name="dg5f_ll_dg_4_4">
    <inertial>
      <origin rpy="0.0 0.0 0.0" xyz="-0.00070816 0.00043036 0.017842"/>
      <inertia ixx="2.8592E-06" ixy="-5.9306E-09" ixz="2.1028E-07" iyy="2.3907E-06" iyz="1.8286E-07" izz="1.6592E-06"/>
      <mass value="0.025"/>
    </inertial>
    <visual>
      <origin rpy="0 0 0" xyz="0 0 0"/>
      <geometry>
        <mesh filename="./meshes/tools/dg5f_left/visual/ll_dg_4_4.dae"/>
      </geometry>
    </visual>
    <collision>
      <origin rpy="0 0 0" xyz="0 0 0"/>
      <geometry>
        <mesh filename="./meshes/tools/dg5f_left/collision/ll_dg_4_4_c.STL"/>
      </geometry>
    </collision>
  </link>
  <joint name="dg5f_lj_dg_4_4" type="revolute">
    <origin rpy="0.0 0.0 0.0" xyz="0.0 0.0 0.0388"/>
    <parent link="dg5f_ll_dg_4_3"/>
    <child link="dg5f_ll_dg_4_4"/>
    <axis xyz="0 1 0"/>
    <limit effort="7.5" lower="-1.5707963267948966" upper="1.5707963267948966" velocity="3.141592653589793"/>
  </joint>
  <link name="dg5f_ll_dg_4_tip">
    <inertial>
      <origin rpy="0.0 0.0 0.0" xyz="0.0038063 5.479E-07 0.007157"/>
      <inertia ixx="3.2445E-07" ixy="2.1191E-12" ixz="1.3375E-08" iyy="1.9895E-07" iyz="-3.0731E-11" izz="2.5698E-07"/>
      <mass value="0.005"/>
    </inertial>
    <visual>
      <origin rpy="0 0 0" xyz="0 0 0"/>
      <geometry>
        <mesh filename="./meshes/tools/dg5f_left/visual/ll_dg_4_tip.dae"/>
      </geometry>
    </visual>
    <collision>
      <origin rpy="0 0 0" xyz="0 0 0"/>
      <geometry>
        <mesh filename="./meshes/tools/dg5f_left/collision/ll_dg_4_tip_c.STL"/>
      </geometry>
    </collision>
  </link>
  <joint name="dg5f_lj_dg_4_tip" type="fixed">
    <origin rpy="0.0 0.0 0.0" xyz="0.0 0.0 0.0255"/>
    <parent link="dg5f_ll_dg_4_4"/>
    <child link="dg5f_ll_dg_4_tip"/>
  </joint>
  <link name="dg5f_ll_dg_5_1">
    <inertial>
      <origin rpy="0.0 0.0 0.0" xyz="-0.0045287 0.025016 0.014025"/>
      <inertia ixx="2.3621E-05" ixy="-2.0571E-07" ixz="2.5894E-06" iyy="2.3655E-05" iyz="-4.4786E-06" izz="1.1298E-05"/>
      <mass value="0.055"/>
    </inertial>
    <visual>
      <origin rpy="0 0 0" xyz="0 0 0"/>
      <geometry>
        <mesh filename="./meshes/tools/dg5f_left/visual/ll_dg_5_1.dae"/>
      </geometry>
    </visual>
    <collision>
      <origin rpy="0 0 0" xyz="0 0 0"/>
      <geometry>
        <mesh filename="./meshes/tools/dg5f_left/collision/ll_dg_5_1_c.STL"/>
      </geometry>
    </collision>
  </link>
  <joint name="dg5f_lj_dg_5_1" type="revolute">
    <origin rpy="0.0 0.0 0.0" xyz="0.0103 0.0195 0.0182"/>
    <parent link="dg5f_ll_dg_palm"/>
    <child link="dg5f_ll_dg_5_1"/>
    <axis xyz="0 0 1"/>
    <limit effort="7.5" lower="-1.0471975511965976" upper="0.017453292519943295" velocity="3.141592653589793"/>
  </joint>
  <link name="dg5f_ll_dg_5_2">
    <inertial>
      <origin rpy="0.0 0.0 0.0" xyz="0.00055633 0.00055633 0.0155"/>
      <inertia ixx="1.9935E-06" ixy="3.114E-09" ixz="1.5774E-07" iyy="1.9935E-06" iyz="-1.5774E-07" izz="1.459E-06"/>
      <mass value="0.025"/>
    </inertial>
    <visual>
      <origin rpy="0 0 0" xyz="0 0 0"/>
      <geometry>
        <mesh filename="./meshes/tools/dg5f_left/visual/ll_dg_5_2.dae"/>
      </geometry>
    </visual>
    <collision>
      <origin rpy="0 0 0" xyz="0 0 0"/>
      <geometry>
        <mesh filename="./meshes/tools/dg5f_left/collision/ll_dg_5_2_c.STL"/>
      </geometry>
    </collision>
  </link>
  <joint name="dg5f_lj_dg_5_2" type="revolute">
    <origin rpy="0.0 0.0 0.0" xyz="0.0 0.028 0.0381"/>
    <parent link="dg5f_ll_dg_5_1"/>
    <child link="dg5f_ll_dg_5_2"/>
    <axis xyz="1 0 0"/>
    <limit effort="7.5" lower="-0.6108652381980153" upper="0.4188790204786391" velocity="3.141592653589793"/>
  </joint>
  <link name="dg5f_ll_dg_5_3">
    <inertial>
      <origin rpy="0.0 0.0 0.0" xyz="4.7446E-06 2.3008E-05 0.014842"/>
      <inertia ixx="6.4181E-06" ixy="-1.3678E-09" ixz="-2.3552E-09" iyy="5.9794E-06" iyz="-3.6014E-07" izz="2.458E-06"/>
      <mass value="0.045"/>
    </inertial>
    <visual>
      <origin rpy="0 0 0" xyz="0 0 0"/>
      <geometry>
        <mesh filename="./meshes/tools/dg5f_left/visual/ll_dg_5_3.dae"/>
      </geometry>
    </visual>
    <collision>
      <origin rpy="0 0 0" xyz="0 0 0"/>
      <geometry>
        <mesh filename="./meshes/tools/dg5f_left/collision/ll_dg_5_3_c.STL"/>
      </geometry>
    </collision>
  </link>
  <joint name="dg5f_lj_dg_5_3" type="revolute">
    <origin rpy="0.0 0.0 0.0" xyz="0.0 0.0 0.031"/>
    <parent link="dg5f_ll_dg_5_2"/>
    <child link="dg5f_ll_dg_5_3"/>
    <axis xyz="0 1 0"/>
    <limit effort="7.5" lower="-1.5707963267948966" upper="1.5707963267948966" velocity="3.141592653589793"/>
  </joint>
  <link name="dg5f_ll_dg_5_4">
    <inertial>
      <origin rpy="0.0 0.0 0.0" xyz="-0.00036539 -0.00020482 0.018795"/>
      <inertia ixx="9.8194E-06" ixy="3.4626E-09" ixz="3.7813E-07" iyy="9.4915E-06" iyz="-1.5157E-07" izz="2.9391E-06"/>
      <mass value="0.045"/>
    </inertial>
    <visual>
      <origin rpy="0 0 0" xyz="0 0 0"/>
      <geometry>
        <mesh filename="./meshes/tools/dg5f_left/visual/ll_dg_5_4.dae"/>
      </geometry>
    </visual>
    <collision>
      <origin rpy="0 0 0" xyz="0 0 0"/>
      <geometry>
        <mesh filename="./meshes/tools/dg5f_left/collision/ll_dg_5_4_c.STL"/>
      </geometry>
    </collision>
  </link>
  <joint name="dg5f_lj_dg_5_4" type="revolute">
    <origin rpy="0.0 0.0 0.0" xyz="0.0 0.0 0.0388"/>
    <parent link="dg5f_ll_dg_5_3"/>
    <child link="dg5f_ll_dg_5_4"/>
    <axis xyz="0 1 0"/>
    <limit effort="7.5" lower="-1.5707963267948966" upper="1.5707963267948966" velocity="3.141592653589793"/>
  </joint>
  <link name="dg5f_ll_dg_5_tip">
    <inertial>
      <origin rpy="0.0 0.0 0.0" xyz="0.0038063 5.479E-07 0.007157"/>
      <inertia ixx="3.2445E-07" ixy="2.1191E-12" ixz="1.3375E-08" iyy="1.9895E-07" iyz="-3.0731E-11" izz="2.5698E-07"/>
      <mass value="0.005"/>
    </inertial>
    <visual>
      <origin rpy="0 0 0" xyz="0 0 0"/>
      <geometry>
        <mesh filename="./meshes/tools/dg5f_left/visual/ll_dg_5_tip.dae"/>
      </geometry>
    </visual>
    <collision>
      <origin rpy="0 0 0" xyz="0 0 0"/>
      <geometry>
        <mesh filename="./meshes/tools/dg5f_left/collision/ll_dg_5_tip_c.STL"/>
      </geometry>
    </collision>
  </link>
  <joint name="dg5f_lj_dg_5_tip" type="fixed">
    <origin rpy="0.0 0.0 0.0" xyz="0.0 0.0 0.0363"/>
    <parent link="dg5f_ll_dg_5_4"/>
    <child link="dg5f_ll_dg_5_tip"/>
  </joint>
  <joint name="rh56_arm_mount" type="fixed">
    <origin rpy="0 0 0" xyz="0.75 -1.3 -0.1"/>
    <parent link="world"/>
    <child link="rh56_base_link"/>
  </joint>
  <joint name="dg5f_arm_mount" type="fixed">
    <origin rpy="0 0 0" xyz="0.75 1.3 -0.1"/>
    <parent link="world"/>
    <child link="dg5f_base_link"/>
  </joint>
  <link name="tilt_shassis">
    <visual>
      <origin rpy="0 0 0" xyz="0 0 0"/>
      <geometry>
        <mesh filename="./meshes/scene/shassis/tilt_shassis.stl"/>
      </geometry>
    </visual>
    <collision>
      <origin rpy="0 0 0" xyz="0 0 0"/>
      <geometry>
        <mesh filename="./meshes/scene/shassis/tilt_shassis.stl"/>
      </geometry>
    </collision>
  </link>
  <joint name="tilt_shassis_mount" type="fixed">
    <origin rpy="0 0 0" xyz="0 0 0"/>
    <parent link="world"/>
    <child link="tilt_shassis"/>
  </joint>
  <!-- Thin collision walls for MoveIt scene -->
  <link name="wall_1">
    <visual>
      <origin rpy="0 0 0" xyz="0 0 0"/>
      <geometry>
        <box size="0.01 6.8 2.0"/>
      </geometry>
      <material name="wall_light_green">
        <color rgba="0.6 1.0 0.6 0.5"/>
      </material>
    </visual>
    <collision>
      <origin rpy="0 0 0" xyz="0 0 0"/>
      <geometry>
        <box size="0.01 6.8 2.0"/>
      </geometry>
    </collision>
  </link>
  <joint name="wall_1_mount" type="fixed">
    <origin rpy="0 0 0" xyz="2.5 0.0 1.0"/>
    <parent link="world"/>
    <child link="wall_1"/>
  </joint>
  <link name="wall_2">
    <visual>
      <origin rpy="0 0 0" xyz="0 0 0"/>
      <geometry>
        <box size="4.0 0.01 2.0"/>
      </geometry>
      <material name="wall_light_green">
        <color rgba="0.6 1.0 0.6 0.5"/>
      </material>
    </visual>
    <collision>
      <origin rpy="0 0 0" xyz="0 0 0"/>
      <geometry>
        <box size="4.0 0.01 2.0"/>
      </geometry>
    </collision>
  </link>
  <joint name="wall_2_mount" type="fixed">
    <origin rpy="0 0 0" xyz="0.5 -3.4 1.0"/>
    <parent link="world"/>
    <child link="wall_2"/>
  </joint>
  <link name="wall_3">
    <visual>
      <origin rpy="0 0 0" xyz="0 0 0"/>
      <geometry>
        <box size="0.01 6.8 2.0"/>
      </geometry>
      <material name="wall_light_green">
        <color rgba="0.6 1.0 0.6 0.5"/>
      </material>
    </visual>
    <collision>
      <origin rpy="0 0 0" xyz="0 0 0"/>
      <geometry>
        <box size="0.01 6.8 2.0"/>
      </geometry>
    </collision>
  </link>
  <joint name="wall_3_mount" type="fixed">
    <origin rpy="0 0 0" xyz="-1.5 0.0 1.0"/>
    <parent link="world"/>
    <child link="wall_3"/>
  </joint>
  <link name="wall_4">
    <visual>
      <origin rpy="0 0 0" xyz="0 0 0"/>
      <geometry>
        <box size="4.0 0.01 2.0"/>
      </geometry>
      <material name="wall_light_green">
        <color rgba="0.6 1.0 0.6 0.5"/>
      </material>
    </visual>
    <collision>
      <origin rpy="0 0 0" xyz="0 0 0"/>
      <geometry>
        <box size="4.0 0.01 2.0"/>
      </geometry>
    </collision>
  </link>
  <joint name="wall_4_mount" type="fixed">
    <origin rpy="0 0 0" xyz="0.5 3.4 1.0"/>
    <parent link="world"/>
    <child link="wall_4"/>
  </joint>
</robot>
